Workbook

Sheet Executive Summary
B2: Refund Root-Cause Analysis - Executive Summary
A5: The cohort in numbers
B7: Total learners (Academy Intake X) | C7: =COUNTA('Master Learner Profile'!B2:B1650) -> 1649
B8: Total refund requests | C8: =COUNTA('Categorised Reasons'!A2:A1650) -> 304
B9: Refunds processed (Refunded? = Yes) | C9: =COUNTIF('Master Learner Profile'!C2:C1650,"Yes") -> 281
B10: Overall refund rate | C10: =COUNTIF('Master Learner Profile'!C2:C1650,"Yes")/COUNTA('Master Learner Profile'!B2:B1650) -> 0.17040631
B11: Avg attendance: refunders | C11: =AVERAGEIFS('Master Learner Profile'!K2:K1650,'Master Learner Profile'!C2:C1650,"Yes") -> 24.574964
B12: Avg attendance: non-refunders | C12: =AVERAGEIFS('Master Learner Profile'!K2:K1650,'Master Learner Profile'!C2:C1650,"No") -> 82.645804
B13: % of refunders who skipped DBWT | C13: =COUNTIFS('Master Learner Profile'!L2:L1650,"No",'Master Learner Profile'!C2:C1650,"Yes")/COUNTIF('Master Learner Profile'!C2:C1650,"Yes") -> 0.4519573
B14: % of refunders in Critical risk segment | C14: =COUNTIFS('Master Learner Profile'!O2:O1650,"1: Critical (No DBWT + No Wk0)",'Master Learner Profile'!C2:C1650,"Yes")/COUNTIF('Master Learner Profile'!C2:C1650,"Yes") -> 0.19928826
A17: The three takeaways
B19: Q1 - Why learners refund | C19: Three buckets cover roughly two-thirds of refund cases: Personal/Family/Medical (~26% of recorded reasons), Career events like new job or relocation (~14%), and Financial difficulty including loan rejection (~21%). The remaining third is operational: course expectation mismatch, time/work pressure, and sales process failures. The operational third is where the lever sits.
B20: Q2 - Can we reduce refund % | C20: Yes, meaningfully. The strongest predictor is whether a learner did the Dashboard Walkthrough: doers refund at ~12%, skippers refund at ~43%. Combined with no Week 0 attendance, refund rate hits ~74%. About 58% of all refunders show one or both early-disengagement signals before they request a refund, which means a precise outreach trigger could touch a small share of the cohort and reach a large share of refunders.
B21: Q3 - What else to dig into | C21: Eight hypotheses listed in the Q3 tab, of which three feel highest-priority: PS/SP rep-level performance as a hidden driver, financial pre-qualification before down payment collection, and learners from non-development backgrounds being under-screened at sales.
A24: How this workbook is organised
B26: Executive Summary | C26: This page
B27: Q1 - Refund Reasons | C27: Categorised refund-reason breakdown plus sub-themes
B28: Q2 - Reduce Refund % | C28: Engagement-vs-refund analysis and the strategies it points to
B29: Q3 - Additional Hypotheses | C29: Open questions that warrant follow-up data
B30: Categorised Reasons | C30: All 304 refund records with my primary-reason tag (data tab)
B31: Master Learner Profile | C31: All 1,649 learners with engagement signals merged + risk segment
B32: Original sheets | C32: Problem Statement, Learner IDs, Comms Tracker, Week 0 Attendance, Overall Attendance, Dashboard Walkthrough, Refund Team Tracker, Mentor Sessions - left untouched

Sheet Problem Statement
B2: Problem Statement: Find the root cause for refunds and generate so-whats
B3: Output Expectation: A clean, formatted .xlsx file answering the questions below
B4: Questions to answer:
B5: 1/ What are the primary reasons our learners request refunds?
B6: 2/ Is there potential to reduce our refund percentage in future intakes? If so, what data-driven strategies can we implement to achieve this reduction?
B7: 3/ Are there any additional hypotheses that would be valuable to explore?
B9: Context on the Problem Statement: https://www.loom.com/share/27fcbbbd010545d9b6a5e423db33815d?sid=88512954-f12c-4315-ab5a-ef89e93c0818
B10: Scaler Context for sheet navigation: https://www.loom.com/share/32019552f04a431bba6d76b92178a9ae?sid=5e280baa-6d8d-48cc-a39f-e31a24b8f00c
B12: Workbook Overview:
B14: Tab Name | C14: Description
B15: Learner IDs | C15: List of all learners in the batch with a tag of learners who requested for a refund
B16: Comms Tracker | C16: Tracker for the communications shared to a learner between the day they enrolled and the start of the program
B17: Week 0 Attendance | C17: Introductory week classes with their attendance (Slug = indication of the type of meeting)
B18: Overall Attendance | C18: Attendance of the learners for their classes (Week 0+1+2)
B19: Dashboard Walkthrough | C19: Tracker for the walkthrough of the dashboard/scaler's internal platform given to a learner before the learners start their classes
B20: Refund Team Tracker | C20: Refund tracker maintained the teams who try to retain the learner with their detailed comments on refund reasons
B21: Mentor Sessions | C21: Mentor sessions tracker for the learners for the few two weeks (booking the session is recommended but optional for the first two weeks)
B23: Additional Instructions:
B24: 1/ Please ensure data hygiene while performing the analysis
B25: 2/ Use formulas wherever possible so that we can trace back your solutions and analysis

Sheet Q1 - Refund Reasons
B2: Q1: What are the primary reasons our learners request refunds?
B4: Approach: I read all 281 free-text refund notes from the Refund Team Tracker, categorised each one into a primary driver based on keyword scoring, and then rolled them up. The full categorised list lives in the "Categorised Reasons" tab.
A6: 1.1 Refund Reasons by Primary Driver (formula-driven from Categorised Reasons tab)
B8: # | C8: Primary Reason | D8: Count | E8: % of 281 | F8: % of 304 reqs | G8: Refund Rate Impact | H8: What the notes typically say
B9: 1 | C9: Personal / Family / Medical | D9: =COUNTIF('Categorised Reasons'!H:H,"Personal / Family / Medical") -> 73 | E9: =IFERROR(D9/(COUNTA('Categorised Reasons'!H2:H305)-COUNTIF('Categorised Reasons'!H:H,"Not Recorded")),0) -> 0.25978648 | F9: =IFERROR(D9/COUNTA('Categorised Reasons'!A2:A305),0) -> 0.24013158 | G9: Drives refunds | H9: Health emergencies, family illness, deaths, marriages, pregnancies, parents not supporting, vague "personal issues"
B10: 2 | C10: New Job / Career Change / Relocation | D10: =COUNTIF('Categorised Reasons'!H:H,"New Job / Career Change / Relocation") -> 38 | E10: =IFERROR(D10/(COUNTA('Categorised Reasons'!H2:H305)-COUNTIF('Categorised Reasons'!H:H,"Not Recorded")),0) -> 0.13523132 | F10: =IFERROR(D10/COUNTA('Categorised Reasons'!A2:A305),0) -> 0.125 | G10: Drives refunds | H10: Got a new job, promotion, onsite project abroad, leaving for US/UK/Germany/Canada, switching domain
B11: 3 | C11: Financial Difficulty / Affordability | D11: =COUNTIF('Categorised Reasons'!H:H,"Financial Difficulty / Affordability") -> 34 | E11: =IFERROR(D11/(COUNTA('Categorised Reasons'!H2:H305)-COUNTIF('Categorised Reasons'!H:H,"Not Recorded")),0) -> 0.12099644 | F11: =IFERROR(D11/COUNTA('Categorised Reasons'!A2:A305),0) -> 0.11184211 | G11: Drives refunds | H11: Sole earner, low salary, lost job, already has loans, can't afford EMI even after enrolling
B12: 4 | C12: Course Expectation / Curriculum Mismatch | D12: =COUNTIF('Categorised Reasons'!H:H,"Course Expectation / Curriculum Mismatch") -> 32 | E12: =IFERROR(D12/(COUNTA('Categorised Reasons'!H2:H305)-COUNTIF('Categorised Reasons'!H:H,"Not Recorded")),0) -> 0.113879 | F12: =IFERROR(D12/COUNTA('Categorised Reasons'!A2:A305),0) -> 0.10526316 | G12: Drives refunds | H12: Wrong fit (QA / testing / non-IT / Project Manager bg), expected ML not DSA, wanted morning batch, said could self-learn
B13: 5 | C13: Time / Work Pressure | D13: =COUNTIF('Categorised Reasons'!H:H,"Time / Work Pressure") -> 32 | E13: =IFERROR(D13/(COUNTA('Categorised Reasons'!H2:H305)-COUNTIF('Categorised Reasons'!H:H,"Not Recorded")),0) -> 0.113879 | F13: =IFERROR(D13/COUNTA('Categorised Reasons'!A2:A305),0) -> 0.10526316 | G13: Drives refunds | H13: 12-13 hour workdays, multiple projects, can't carve out 9-12 hrs/week for live classes
B14: 6 | C14: Loan / NBFC / Financing Issue | D14: =COUNTIF('Categorised Reasons'!H:H,"Loan / NBFC / Financing Issue") -> 24 | E14: =IFERROR(D14/(COUNTA('Categorised Reasons'!H2:H305)-COUNTIF('Categorised Reasons'!H:H,"Not Recorded")),0) -> 0.085409253 | F14: =IFERROR(D14/COUNTA('Categorised Reasons'!A2:A305),0) -> 0.078947368 | G14: Drives refunds | H14: Loan rejected by NBFC partners (low CIBIL, no co-applicant, low banking, short credit history)
B15: 7 | C15: Sales / Service Process Issue | D15: =COUNTIF('Categorised Reasons'!H:H,"Sales / Service Process Issue") -> 15 | E15: =IFERROR(D15/(COUNTA('Categorised Reasons'!H2:H305)-COUNTIF('Categorised Reasons'!H:H,"Not Recorded")),0) -> 0.053380783 | F15: =IFERROR(D15/COUNTA('Categorised Reasons'!A2:A305),0) -> 0.049342105 | G15: Drives refunds | H15: Delay in revert from PS/SP, wrong information at sales, alumni feedback negative, BDA inactive in system
B16: 8 | C16: Higher Studies / Govt Career | D16: =COUNTIF('Categorised Reasons'!H:H,"Higher Studies / Govt Career") -> 3 | E16: =IFERROR(D16/(COUNTA('Categorised Reasons'!H2:H305)-COUNTIF('Categorised Reasons'!H:H,"Not Recorded")),0) -> 0.010676157 | F16: =IFERROR(D16/COUNTA('Categorised Reasons'!A2:A305),0) -> 0.0098684211 | G16: Drives refunds | H16: Cleared UPSC, going for Masters abroad, joining army
B17: 9 | C17: Pricing / Value Concern | D17: =COUNTIF('Categorised Reasons'!H:H,"Pricing / Value Concern") -> 2 | E17: =IFERROR(D17/(COUNTA('Categorised Reasons'!H2:H305)-COUNTIF('Categorised Reasons'!H:H,"Not Recorded")),0) -> 0.0071174377 | F17: =IFERROR(D17/COUNTA('Categorised Reasons'!A2:A305),0) -> 0.0065789474 | G17: Drives refunds | H17: Felt course not worth the price, others got it cheaper, asking too much for what is offered
B18: 10 | C18: Other / Unclear | D18: =COUNTIF('Categorised Reasons'!H:H,"Other / Unclear") -> 28 | E18: =IFERROR(D18/(COUNTA('Categorised Reasons'!H2:H305)-COUNTIF('Categorised Reasons'!H:H,"Not Recorded")),0) -> 0.099644128 | F18: =IFERROR(D18/COUNTA('Categorised Reasons'!A2:A305),0) -> 0.092105263 | G18: Drives refunds | H18: Vague, mixed, or unclear notes that don't cluster into one driver
B19: 11 | C19: Not Recorded | D19: =COUNTIF('Categorised Reasons'!H:H,"Not Recorded") -> 23 | E19: =IFERROR(D19/(COUNTA('Categorised Reasons'!H2:H305)-COUNTIF('Categorised Reasons'!H:H,"Not Recorded")),0) -> 0.081850534 | F19: =IFERROR(D19/COUNTA('Categorised Reasons'!A2:A305),0) -> 0.075657895 | G19: Drives refunds | H19: Refund row exists but no detailed reason field was filled in by the team
C20: TOTAL | D20: =SUM(D9:D19) -> 304
C21: Total with reason text: | D21: =COUNTA('Categorised Reasons'!F2:F305) -> 281
C22: Total refund requests: | D22: =COUNTA('Categorised Reasons'!A2:A305) -> 304
A25: 1.2 Headline insight
B27: Roughly two thirds of refund requests cluster into three buckets: Personal/Family/Medical (~26% of cases with a recorded reason), Career-related events like a new job or relocation (~14%), and Financial Difficulty including loan rejections (~21% combined when you add Loan/NBFC + Affordability). What is striking is that the remaining third splits into reasons Scaler can actually act on: course expectation mismatch (~11%), time/work pressure (~11%), and sales process issues (~5%). These three are the operational levers worth pulling, because a learner whose father is in hospital is hard to retain, but a learner who thought the course was 3 hours a week and discovered it is 9 is a fixable problem.
A30: 1.3 Sub-themes within the major buckets (qualitative)
B32: Bucket | C32: Recurring sub-themes I saw in the notes
B33: Personal / Family / Medical | C33: Family member hospitalised (father, grandmother, parent), own surgery or medical condition, pregnancy, newly married, family pressure or parents not supportive of upskilling. Often paired with a "will rejoin in 3-6 months" intent.
B34: New Job / Career Change / Relocation | C34: Got placed mid-program, onsite project to US/UK/Germany/Sweden/Mexico/Vietnam, L1 visa, Canada PR approved, or moving for spouse. A subset is "switching domain" where the learner decides development is not their long-term path after a few classes.
B35: Financial / Loan | C35: Loan rejected by NBFC partners (low CIBIL, no co-applicant, salary too low, AQBB norms), or learner is sole earner / lost job / already has 2-3 loans. Several mention they paid down-payment expecting loan approval and got blindsided.
B36: Course Expectation Mismatch | C36: "I thought it was 3-4 hrs/week, it is 9", "I thought class size was 100, it is 220", wanted morning batch, came from QA / testing / digital marketing / project management and felt the dev focus was wrong, expected DSML but got DSA, expected job guarantee.
B37: Time / Work Pressure | C37: 12-13 hour work days, multiple parallel projects assigned, overlapping IST/EST/PST shifts, newly added team responsibilities, internal courses pushed by employer competing for time.
B38: Sales / Service Process | C38: Delay in revert from PS or SP after refund request raised (multiple cases say "transferred due to breach in timelines, reason unknown"), wrong information at the sales stage, alumni gave bad feedback when the learner cross-checked, BDA inactive in system.

Sheet Q2 - Reduce Refund %
B2: Q2: Can we reduce refund % in future intakes? What strategies?
B4: Approach: I joined every learner's engagement signal (comms opens, Week 0 attendance, Dashboard Walkthrough completion, overall attendance, mentor sessions) onto the master roster of 1,649 learners and split refund rate by each signal. The full merged data lives in "Master Learner Profile" tab. All counts below are formulas pointing at that tab so they update if the underlying data changes.
A6: 2.1 The headline numbers
B8: Metric | C8: Value | D8: Formula source
B9: Total learners in batch | C9: =COUNTA('Master Learner Profile'!B2:B1650) -> 1649 | D9: COUNTA of Learner ID column
B10: Total refunds | C10: =COUNTIF('Master Learner Profile'!C2:C1650,"Yes") -> 281 | D10: COUNTIF Refunded? = Yes
B11: Overall refund rate | C11: =COUNTIF('Master Learner Profile'!C2:C1650,"Yes")/COUNTA('Master Learner Profile'!B2:B1650) -> 0.17040631 | D11: Refunds / Total
B12: Refunders avg overall attendance | C12: =AVERAGEIFS('Master Learner Profile'!K2:K1650,'Master Learner Profile'!C2:C1650,"Yes") -> 24.574964 | D12: AVERAGEIFS on Overall Attendance where Refunded=Yes
B13: Non-refunders avg overall attendance | C13: =AVERAGEIFS('Master Learner Profile'!K2:K1650,'Master Learner Profile'!C2:C1650,"No") -> 82.645804 | D13: AVERAGEIFS on Overall Attendance where Refunded=No
B14: Gap (non-refund minus refund) | C14: =AVERAGEIFS('Master Learner Profile'!K2:K1650,'Master Learner Profile'!C2:C1650,"No")-AVERAGEIFS('Master Learner Profile'!K2:K1650,'Master Learner Profile'!C2:C1650,"Yes") -> 58.07084 | D14: Difference of the two means
A17: 2.2 Refund rate by Overall Attendance bucket
B19: Attendance bucket | C19: Total learners | D19: Refunders | E19: Non-refunders | F19: Refund rate %
B20: 0% (no shows) | C20: =SUMPRODUCT(--('Master Learner Profile'!K2:K1650=0)) -> 91 | D20: =SUMPRODUCT(--('Master Learner Profile'!K2:K1650=0),--('Master Learner Profile'!C2:C1650="Yes")) -> 73 | E20: =SUMPRODUCT(--('Master Learner Profile'!K2:K1650=0),--('Master Learner Profile'!C2:C1650="No")) -> 18 | F20: =IFERROR(D20/C20,0) -> 0.8021978
B21: 1% to 25% | C21: =SUMPRODUCT(--('Master Learner Profile'!K2:K1650>0),--('Master Learner Profile'!K2:K1650<=25)) -> 175 | D21: =SUMPRODUCT(--('Master Learner Profile'!K2:K1650>0),--('Master Learner Profile'!K2:K1650<=25),--('Master Learner Profile'!C2:C1650="Yes")) -> 94 | E21: =SUMPRODUCT(--('Master Learner Profile'!K2:K1650>0),--('Master Learner Profile'!K2:K1650<=25),--('Master Learner Profile'!C2:C1650="No")) -> 81 | F21: =IFERROR(D21/C21,0) -> 0.53714286
B22: 25% to 50% | C22: =SUMPRODUCT(--('Master Learner Profile'!K2:K1650>25),--('Master Learner Profile'!K2:K1650<=50)) -> 155 | D22: =SUMPRODUCT(--('Master Learner Profile'!K2:K1650>25),--('Master Learner Profile'!K2:K1650<=50),--('Master Learner Profile'!C2:C1650="Yes")) -> 68 | E22: =SUMPRODUCT(--('Master Learner Profile'!K2:K1650>25),--('Master Learner Profile'!K2:K1650<=50),--('Master Learner Profile'!C2:C1650="No")) -> 87 | F22: =IFERROR(D22/C22,0) -> 0.43870968
B23: 50% to 75% | C23: =SUMPRODUCT(--('Master Learner Profile'!K2:K1650>50),--('Master Learner Profile'!K2:K1650<=75)) -> 163 | D23: =SUMPRODUCT(--('Master Learner Profile'!K2:K1650>50),--('Master Learner Profile'!K2:K1650<=75),--('Master Learner Profile'!C2:C1650="Yes")) -> 30 | E23: =SUMPRODUCT(--('Master Learner Profile'!K2:K1650>50),--('Master Learner Profile'!K2:K1650<=75),--('Master Learner Profile'!C2:C1650="No")) -> 133 | F23: =IFERROR(D23/C23,0) -> 0.18404908
B24: 75% to 90% | C24: =SUMPRODUCT(--('Master Learner Profile'!K2:K1650>75),--('Master Learner Profile'!K2:K1650<=90)) -> 247 | D24: =SUMPRODUCT(--('Master Learner Profile'!K2:K1650>75),--('Master Learner Profile'!K2:K1650<=90),--('Master Learner Profile'!C2:C1650="Yes")) -> 9 | E24: =SUMPRODUCT(--('Master Learner Profile'!K2:K1650>75),--('Master Learner Profile'!K2:K1650<=90),--('Master Learner Profile'!C2:C1650="No")) -> 238 | F24: =IFERROR(D24/C24,0) -> 0.036437247
B25: 90% to 100% | C25: =SUMPRODUCT(--('Master Learner Profile'!K2:K1650>=90),--('Master Learner Profile'!K2:K1650<=100)) -> 818 | D25: =SUMPRODUCT(--('Master Learner Profile'!K2:K1650>=90),--('Master Learner Profile'!K2:K1650<=100),--('Master Learner Profile'!C2:C1650="Yes")) -> 7 | E25: =SUMPRODUCT(--('Master Learner Profile'!K2:K1650>=90),--('Master Learner Profile'!K2:K1650<=100),--('Master Learner Profile'!C2:C1650="No")) -> 811 | F25: =IFERROR(D25/C25,0) -> 0.0085574572
B26: TOTAL | C26: =SUM(C20:C25) -> 1649 | D26: =SUM(D20:D25) -> 281 | E26: =SUM(E20:E25) -> 1368 | F26: =IFERROR(D26/C26,0) -> 0.17040631
B28: Insight: Attendance and refund are almost perfectly inversely correlated. Above 90% attendance the refund rate collapses to under 1%. Below 25% attendance more than half of learners ask for a refund. This is not just because refunders stop attending after deciding to leave, the timing data shows most refund requests are raised within the first 14 days, before attendance has had time to decay much. So low Week 0 to Week 2 attendance is a real leading indicator, not a lagging one.
A31: 2.3 Refund rate by Dashboard Walkthrough (DBWT) completion
B33: DBWT status | C33: Total learners | D33: Refunders | E33: Non-refunders | F33: Refund rate % | G33: Read note
B34: Yes (DBWT done) | C34: =COUNTIF('Master Learner Profile'!L2:L1650,"Yes") -> 1275 | D34: =COUNTIFS('Master Learner Profile'!L2:L1650,"Yes",'Master Learner Profile'!C2:C1650,"Yes") -> 154 | E34: =COUNTIFS('Master Learner Profile'!L2:L1650,"Yes",'Master Learner Profile'!C2:C1650,"No") -> 1121 | F34: =IFERROR(D34/C34,0) -> 0.12078431 | G34: Did the dashboard walkthrough
B35: No (DBWT not done) | C35: =COUNTIF('Master Learner Profile'!L2:L1650,"No") -> 295 | D35: =COUNTIFS('Master Learner Profile'!L2:L1650,"No",'Master Learner Profile'!C2:C1650,"Yes") -> 127 | E35: =COUNTIFS('Master Learner Profile'!L2:L1650,"No",'Master Learner Profile'!C2:C1650,"No") -> 168 | F35: =IFERROR(D35/C35,0) -> 0.43050847 | G35: Walkthrough scheduled but did not show / declined
B36: Not Tracked (no DBWT row) | C36: =COUNTIF('Master Learner Profile'!L2:L1650,"Not Tracked") -> 79 | D36: =COUNTIFS('Master Learner Profile'!L2:L1650,"Not Tracked",'Master Learner Profile'!C2:C1650,"Yes") -> 0 | E36: =COUNTIFS('Master Learner Profile'!L2:L1650,"Not Tracked",'Master Learner Profile'!C2:C1650,"No") -> 79 | F36: =IFERROR(D36/C36,0) -> 0 | G36: Did not appear in DBWT sheet at all
B38: Insight: Skipping the Dashboard Walkthrough is the single strongest pre-class signal we have. Learners who skipped it refunded at roughly 3 to 4 times the rate of those who attended. Note also that the small group "Not Tracked" has effectively no refunds, which suggests these are likely late enrollees or learners onboarded outside the standard flow. Worth confirming with the ops team.
A40: 2.4 Refund rate by combined Risk Segment
B41: Risk segment combines two signals: (a) did the learner do the Dashboard Walkthrough, and (b) did they attend any Week 0 session. The segment is computed in column O of Master Learner Profile.
B43: Risk Segment | C43: Total learners | D43: Refunders | E43: Non-refunders | F43: Refund rate % | G43: % of all refunders
B44: 1: Critical (No DBWT + No Wk0) | C44: =COUNTIF('Master Learner Profile'!O2:O1650,"1: Critical (No DBWT + No Wk0)") -> 76 | D44: =COUNTIFS('Master Learner Profile'!O2:O1650,"1: Critical (No DBWT + No Wk0)",'Master Learner Profile'!C2:C1650,"Yes") -> 56 | E44: =COUNTIFS('Master Learner Profile'!O2:O1650,"1: Critical (No DBWT + No Wk0)",'Master Learner Profile'!C2:C1650,"No") -> 20 | F44: =IFERROR(D44/C44,0) -> 0.73684211 | G44: =IFERROR(D44/COUNTIF('Master Learner Profile'!C2:C1650,"Yes"),0) -> 0.19928826
B45: 2: High (No DBWT) | C45: =COUNTIF('Master Learner Profile'!O2:O1650,"2: High (No DBWT)") -> 219 | D45: =COUNTIFS('Master Learner Profile'!O2:O1650,"2: High (No DBWT)",'Master Learner Profile'!C2:C1650,"Yes") -> 71 | E45: =COUNTIFS('Master Learner Profile'!O2:O1650,"2: High (No DBWT)",'Master Learner Profile'!C2:C1650,"No") -> 148 | F45: =IFERROR(D45/C45,0) -> 0.32420091 | G45: =IFERROR(D45/COUNTIF('Master Learner Profile'!C2:C1650,"Yes"),0) -> 0.25266904
B46: 3: Elevated (No Wk0) | C46: =COUNTIF('Master Learner Profile'!O2:O1650,"3: Elevated (No Wk0)") -> 88 | D46: =COUNTIFS('Master Learner Profile'!O2:O1650,"3: Elevated (No Wk0)",'Master Learner Profile'!C2:C1650,"Yes") -> 37 | E46: =COUNTIFS('Master Learner Profile'!O2:O1650,"3: Elevated (No Wk0)",'Master Learner Profile'!C2:C1650,"No") -> 51 | F46: =IFERROR(D46/C46,0) -> 0.42045455 | G46: =IFERROR(D46/COUNTIF('Master Learner Profile'!C2:C1650,"Yes"),0) -> 0.1316726
B47: 4: Engaged Early | C47: =COUNTIF('Master Learner Profile'!O2:O1650,"4: Engaged Early") -> 1266 | D47: =COUNTIFS('Master Learner Profile'!O2:O1650,"4: Engaged Early",'Master Learner Profile'!C2:C1650,"Yes") -> 117 | E47: =COUNTIFS('Master Learner Profile'!O2:O1650,"4: Engaged Early",'Master Learner Profile'!C2:C1650,"No") -> 1149 | F47: =IFERROR(D47/C47,0) -> 0.092417062 | G47: =IFERROR(D47/COUNTIF('Master Learner Profile'!C2:C1650,"Yes"),0) -> 0.41637011
A50: 2.5 Data-driven strategies to reduce refund %
B52: # | C52: Strategy | D52: Why it works (data trail)
B53: 1 | C53: Make Dashboard Walkthrough effectively non-skippable | D53: Learners who did DBWT refunded at ~12% versus ~43% for those who skipped. That gap is too large to be coincidence. Make it required for class access (or delay first live class invite until DBWT is done), and have a sales-side call-back loop kicked off if DBWT remains undone within 48 hours of enrollment.
B54: 2 | C54: Build an early-warning trigger for "Critical" risk segment | D54: 76 learners fell into the No-DBWT-and-No-Week0 bucket. 56 of them (~74%) refunded. That is an extremely tight predictor. A simple rule that fires a personal outreach call within 72 hours of batch start for anyone in this segment would touch only ~5% of the cohort but cover ~20% of all refunders.
B55: 3 | C55: Tighten financial qualification at sales | D55: 21% of recorded refund reasons trace back to loan rejection or post-enrollment affordability shock. These are people we accepted into the program despite financial constraints we could have seen. A pre-enrollment soft credit pull, plus a "you must have a co-applicant on file" rule before DP is collected, would catch most of these before they become refund cases.
B56: 4 | C56: Fix expectation gaps at the sales pitch | D56: Course expectation mismatch covers ~11-15% of refund reasons, and the recurring complaints are very specific: "told it was 3-4 hrs, it is 9", "told class size 100, it is 220", "I am from QA / project management, this is too dev-heavy", "I wanted morning batch". A standardised pre-enrollment fact sheet plus a 5-minute role-fit screen at sales would prevent almost all of these.
B57: 5 | C57: Service-level commitment for refund-flag escalations | D57: The notes contain a distinct sub-pattern of "no revert from SP/PS, hence had to transfer due to delay in timelines, full refund approved by HP". These are refunds that were process failures, not learner failures. A 24-hour SLA on retention call-backs, with auto-escalation to a manager if missed, would recover the ~5% of refunds that fall in this bucket.
...

Sheet Q3 - Additional Hypotheses
B2: Q3: Additional hypotheses worth exploring
B4: These are hypotheses I could not fully resolve with the data shared, but the patterns were strong enough that they are worth investigating in a follow-up cut. Each one identifies the data that would be needed to confirm or kill it.
B6: # | C6: Hypothesis | D6: What I see in the data and why I think it matters | E6: How to test it | F6: Likely lever if true
B7: 1 | C7: PS or SP rep performance is a hidden driver | D7: A handful of PS / SP names recur across delayed-revert refund notes: cases where the refund reason ends up being "no response from SP, transferred due to breach in timelines". Some reps might also be over-promising at the sales stage. There is also a cluster of cases where the BDA who originally signed the learner is described as "not active in the system anymore". | E7: Tag every refund record with the SP/PS/BDA who owned it. Compute refund rate by rep. Look for reps with refund rates more than 1.5x the cohort average. Cross-check with average response time from the comms tracker. | F7: Targeted coaching, SLA enforcement, BDA handover process
B8: 2 | C8: Learners enrolled within 7 days of batch start are higher risk | D8: The Comms Tracker has a "Week" column going from T-4 (4 weeks before start) to T-1 (1 week before). Learners with comms only at T-1 had less time to do DBWT, attend Week 0, or even read the welcome sequence. Worth testing whether late enrollees refund at a higher rate. | E8: Use the comms T-week minimum per learner as a proxy for enrollment-to-start lead time. Bucket the cohort by lead time and compute refund rate per bucket. | F8: Cap late enrollments, or auto-defer to next batch
B9: 3 | C9: Learners from non-development backgrounds (QA, testing, project management, digital marketing, older non-IT professionals) refund at higher rates | D9: The free-text notes contain repeated mentions of QA, testing, project manager with 16 yrs exp, digital marketing background, sole proprietor of a petrol pump for 17 years, etc. A meaningful chunk of refunders had a fundamental fit problem that should have been caught at sales. | E9: Capture self-declared current role / years of experience at enrollment. Refund rate by background segment will tell us whether sales is qualifying these learners well enough. | F9: Better pre-sales fit screening, separate cohorts for non-dev backgrounds
B10: 4 | C10: Loan rejection causes both direct refunds AND a hidden retention drag | D10: Direct loan-rejection refunds are about 8% of cases. But the underlying issue (down payment paid, then loan rejected) probably causes anxiety even in learners who eventually do find a way to pay. Some financial-difficulty refunds may originate from a stressful loan saga. | E10: Tag every learner with whether their loan went through cleanly, was approved late, or was rejected and the gap was filled differently. Compare refund rate and engagement across the three groups. | F10: Pre-qualify loan eligibility before DP collection
B11: 5 | C11: Refund decision is largely made by Day 7-10, regardless of when it is filed | D11: Refund requests cluster heavily in days 7-14 after batch start. But the engagement collapse (no DBWT, no Week 0) happens before that. The decision is probably formed in the first week, and the request is filed once the learner is sure. | E11: Time-stamp the engagement signals and check the gap between "first signal of disengagement" (missed first class, missed DBWT) and "refund request filed". If average gap is more than 5 days we have a recoverable retention window we are not using. | F11: Day-3 and Day-7 personal outreach for at-risk learners
B12: 6 | C12: Comms open rate is not predictive but comms click rate might be | D12: Aggregate open rates are nearly identical for refunders (~68%) and non-refunders (~70%). Click rates are slightly lower for refunders (~14% vs ~16%). Opens are noisy (auto-pixel-loading inflates them), clicks are a much stronger intent signal. | E12: Look at click rate distribution by refund status. Test whether learners with zero clicks across the entire pre-batch comms cycle have elevated refund rates. | F12: Use zero-click learners as an additional risk flag
B13: 7 | C13: Pricing inconsistency erodes trust | D13: At least one note explicitly says "I got the course for 2.9L while my batchmates got it for 2.1L, so I lost interest". This is anecdotal here but could be a wider issue if discount structures are inconsistent. | E13: Look at fee paid distribution within the same batch. If standard deviation is high, that is a signal. Survey learners who heard about peers paying less. | F13: Standardised pricing or transparent discount tiers
B14: 8 | C14: Mentor sessions could be retention-positive if mandatory rather than optional | D14: Mentor sessions are described as recommended-but-optional for the first two weeks. Booking rate is low (~10%) and refund rate among bookers is barely different from non-bookers. But that may just be self-selection: the bookers were already engaged. A mandatory first mentor session in Week 1 might pull at-risk learners into a human conversation. | E14: Run an A/B in the next intake: half the cohort gets a scheduled-by-default mentor session in Week 1, half does not. Compare refund rates. | F14: Mandatory week-1 mentor session

Sheet Categorised Reasons
A1: Learner ID | B1: Refund Request Date | C1: Stage | D1: Within Refund Window | E1: Days from Batch Start | F1: Detailed Reason | G1: Refund Type | H1: Primary Reason
A2: AIX11549 | B2: 44768 | C2: Retained | D2: Within Refund window | E2: 14 | H2: Not Recorded
A3: AIX11402 | B3: 44767 | C3: Retained | D3: Within Refund window | E3: 13 | F3: The learner does not see the value in the program and believes he can achieve the outcomes on his own as he has people in the industry he knows being a developer for 4 yrs. He appreciated the quality of the program but says its not up to the monetary value. Informed by SP Mr. Varun Awasthi | G3: Full Refund | H3: Course Expectation / Curriculum Mismatch
A4: AIX10761 | B4: 44767 | C4: Retained | D4: Within Refund window | E4: 13 | H4: Not Recorded
A5: AIX10413 | B5: 44767 | C5: Retained | D5: Within Refund window | E5: 13 | H5: Not Recorded
A6: AIX11026 | B6: 44767 | C6: Retained | D6: Within Refund window | E6: 13 | H6: Not Recorded
A7: AIX10998 | B7: 44767 | C7: Retained | D7: Within Refund window | E7: 13 | H7: Not Recorded
A8: AIX11170 | B8: 44766 | C8: Retained | D8: Within Refund window | E8: 12 | H8: Not Recorded
A9: AIX11541 | B9: 44766 | C9: Retained | D9: Within Refund window | E9: 12 | H9: Not Recorded
A10: AIX10749 | B10: 44766 | C10: Retained | D10: Within Refund window | E10: 12 | H10: Not Recorded
A11: AIX10070 | B11: 44765 | C11: Retained | D11: Within Refund window | E11: 11 | H11: Not Recorded
A12: AIX11647 | B12: 44765 | C12: Retained | D12: Within Refund window | E12: 11 | H12: Not Recorded
A13: AIX10397 | B13: 44762 | C13: Retained | D13: Within Refund window | E13: 8 | H13: Not Recorded
A14: AIX11191 | B14: 44761 | C14: Retained | D14: Within Refund window | E14: 7 | H14: Not Recorded
A15: AIX11230 | B15: 44760 | C15: Retained | D15: Within Refund window | E15: 6 | H15: Not Recorded
... A21: AIX11044 | B21: 44757 | C21: Retained | D21: Within Refund window | E21: 3 | H21: Not Recorded
A22: AIX11619 | B22: 44754 | C22: Refund Closed | D22: Within Refund window | E22: 0 | F22: The learner has many interviews lined up and doesn't have time to attend classes. | G22: Full Refund | H22: New Job / Career Change / Relocation
A23: AIX10179 | B23: 44751 | C23: Retained | D23: Within Refund window | E23: -3 | H23: Not Recorded
A24: AIX11582 | B24: 44734 | C24: Retained | D24: Within Refund window | E24: -20 | H24: Not Recorded
A25: AIX11544 | B25: 44731 | C25: DB to be Deactived | D25: Within Refund window | E25: -23 | F25: The learner has some personal issues and hence wants to go ahead with the refund, this was initially retained from SPs but the cx was adamant for a refund | G25: Full Refund | H25: Personal / Family / Medical
A26: AIX11627 | B26: 44736 | C26: DB to be Deactived | D26: Within Refund window | E26: -18 | F26: His CC is not listed in no cost EMI and he doesn't want to go for the loan. Informed by Ms. Annu Kumari | G26: Full Refund | H26: Loan / NBFC / Financing Issue
A27: AIX10256 | B27: 44738 | C27: DB to be Deactived | D27: Within Refund window | E27: -16 | F27: This learner has some personal issues due to which he does not want to continue with us | G27: Full Refund | H27: Personal / Family / Medical
A28: AIX10097 | B28: 44739 | C28: DB to be Deactived | D28: Within Refund window | E28: -15 | F28: This learner has family issues due to which he cannot continue with us | G28: Full Refund | H28: Personal / Family / Medical
A29: AIX10010 | B29: 44739 | C29: DB to be Deactived | D29: Within Refund window | E29: -15 | F29: His loan is not getting sanctioned and he doesn't have any co applicant to give | G29: Full Refund | H29: Loan / NBFC / Financing Issue
A30: AIX10665 | B30: 44739 | C30: DB to be Deactived | D30: Within Refund window | E30: -15 | F30: No update from PS nor SP despite multiple reminder, this learner was initially retained by SP Mr. Kuppa Nagarjuna but later the cx followed up for a refund and hence had to be processed as request is wrp | G30: Full Refund | H30: Sales / Service Process Issue
A31: AIX10031 | B31: 44739 | C31: DB to be Deactived | D31: Within Refund window | E31: -15 | F31: This learner doesnt want to go ahead with loan process as his family members are not supporting. | G31: Full Refund | H31: Loan / NBFC / Financing Issue
A32: AIX10222 | B32: 44738 | C32: DB to be Deactived | D32: Within Refund window | E32: -16 | F32: This learner is going through some financial emergency at his end at the moment so he will not be able to go ahead currently. Informed by SP | G32: Full Refund | H32: Financial Difficulty / Affordability
A33: AIX10007 | B33: 44741 | C33: DB to be Deactived | D33: Within Refund window | E33: -13 | F33: This learner has some personal major issues due to which he could not proceed further. | G33: Full Refund | H33: Personal / Family / Medical
A34: AIX10012 | B34: 44741 | C34: DB to be Deactived | D34: Within Refund window | E34: -13 | F34: There was no proper update from the sales team regarding this cx. The learner kept following up and hence had to push further to finance team | G34: Full Refund | H34: Sales / Service Process Issue
A35: AIX10109 | B35: 44742 | C35: DB to be Deactived | D35: Within Refund window | E35: -12 | F35: The learner has some family issue currently, her mental state is not fine. She needs a break and might join after few months. | G35: Full Refund | H35: Personal / Family / Medical
A36: AIX11547 | B36: 44742 | C36: DB to be Deactived | D36: Within Refund window | E36: -12 | F36: The learner was never interested in the course. We changed his class timings and addressed whatever complains he had. We worked on that now he comes up with another reason saying instructor is less experienced than his experience. He doesn't want the course. Informed by PS Ms. Sonam Thakur | G36: Full Refund | H36: Course Expectation / Curriculum Mismatch
... A54: AIX10044 | B54: 44748 | C54: DB to be Deactived | D54: Within Refund window | E54: -6 | F54: This learner has some medical emergency as informed by SP Mr. Ujjwal Saini. | G54: Full Refund | H54: Personal / Family / Medical
A55: AIX10119 | B55: 44746 | C55: DB to be Deactived | D55: Within Refund window | F55: This learner feels the company policies are not that fair, the learner feels he was pressurized by the SPs to pay the amount. The learner felt extremely harassed for a whole day by constant calls from every direction to join and to pay right now. The learner just wants to get out of this course asap. Hence refund | G55: Full Refund | H55: Sales / Service Process Issue
A56: AIX11356 | B56: 44746 | C56: DB to be Deactived | D56: Within Refund window | F56: This learner does not want any third party loan | G56: Full Refund | H56: Other / Unclear
A57: AIX10261 | B57: 44746 | C57: DB to be Deactived | D57: Within Refund window | F57: This learner got an offer from a different organization, next day after her enrolment. Hence refund | G57: Full Refund | H57: New Job / Career Change / Relocation
A58: AIX10005 | B58: 44745 | C58: UTR Details to be shared to candidate | D58: Within Refund window | F58: Duplicate entry | H58: Sales / Service Process Issue
A59: AIX11468 | B59: 44745 | C59: DB to be Deactived | D59: Within Refund window | F59: personal reason | G59: Full Refund | H59: Personal / Family / Medical
A60: AIX10018 | B60: 44749 | C60: DB to be Deactived | D60: Within Refund window | E60: -5 | F60: The learner's father passed away and she is not in a state to move ahead. | G60: Full Refund | H60: Personal / Family / Medical
A61: AIX10112 | B61: 44749 | C61: DB to be Deactived | D61: Within Refund window | E61: -5 | F61: This learner has financial issues going on in his family, hence refund | G61: Full Refund | H61: Financial Difficulty / Affordability
A62: AIX10215 | B62: 44750 | C62: DB to be Deactived | D62: Within Refund window | E62: -4 | F62: cx is really adamant for a refund.informed by SP | G62: Full Refund | H62: Other / Unclear
...

Sheet Master Learner Profile
A1: Batch | B1: Learner ID | C1: Refunded? | D1: Comms Delivered | E1: Comms Opened | F1: Comms Clicked | G1: Open Rate | H1: Click Rate | I1: Week 0 Sessions Attended | J1: Week 0 Avg Attendance | K1: Overall Attendance % | L1: Dashboard Walkthrough Done | M1: Mentor Sessions Booked | N1: Engagement Score | O1: Risk Segment
A2: Academy Intake X | B2: AIX10001 | C2: Yes | D2: 22 | E2: 6 | F2: 3 | G2: =IFERROR(E2/D2,0) -> 0.27272727 | H2: =IFERROR(F2/D2,0) -> 0.13636364 | I2: 1 | J2: 75.83 | K2: 18.96 | L2: Yes | M2: 0 | N2: =ROUND(IFERROR(K2/100,0)*0.6 + IF(L2="Yes",1,IF(L2="No",0,0.3))*0.25 + IFERROR(J2/100,0)*0.15,3) -> 0.478 | O2: =IF(AND(L2="No",I2=0),"1: Critical (No DBWT + No Wk0)",IF(L2="No","2: High (No DBWT)",IF(I2=0,"3: Elevated (No Wk0)","4: Engaged Early"))) -> 4: Engaged Early
A3: Academy Intake X | B3: AIX10002 | C3: Yes | D3: 2 | E3: 2 | F3: 1 | G3: =IFERROR(E3/D3,0) -> 1 | H3: =IFERROR(F3/D3,0) -> 0.5 | I3: 1 | J3: 85.42 | K3: 12.5 | L3: No | M3: 0 | N3: =ROUND(IFERROR(K3/100,0)*0.6 + IF(L3="Yes",1,IF(L3="No",0,0.3))*0.25 + IFERROR(J3/100,0)*0.15,3) -> 0.203 | O3: =IF(AND(L3="No",I3=0),"1: Critical (No DBWT + No Wk0)",IF(L3="No","2: High (No DBWT)",IF(I3=0,"3: Elevated (No Wk0)","4: Engaged Early"))) -> 2: High (No DBWT)
A4: Academy Intake X | B4: AIX10003 | C4: No | D4: 4 | E4: 2 | F4: 1 | G4: =IFERROR(E4/D4,0) -> 0.5 | H4: =IFERROR(F4/D4,0) -> 0.25 | I4: 0 | K4: 0 | L4: No | M4: 0 | N4: =ROUND(IFERROR(K4/100,0)*0.6 + IF(L4="Yes",1,IF(L4="No",0,0.3))*0.25 + IFERROR(J4/100,0)*0.15,3) -> 0 | O4: =IF(AND(L4="No",I4=0),"1: Critical (No DBWT + No Wk0)",IF(L4="No","2: High (No DBWT)",IF(I4=0,"3: Elevated (No Wk0)","4: Engaged Early"))) -> 1: Critical (No DBWT + No Wk0)
A5: Academy Intake X | B5: AIX10004 | C5: Yes | D5: 13 | E5: 11 | F5: 1 | G5: =IFERROR(E5/D5,0) -> 0.84615385 | H5: =IFERROR(F5/D5,0) -> 0.076923077 | I5: 1 | J5: 98.5153 | K5: 16.02 | L5: No | M5: 0 | N5: =ROUND(IFERROR(K5/100,0)*0.6 + IF(L5="Yes",1,IF(L5="No",0,0.3))*0.25 + IFERROR(J5/100,0)*0.15,3) -> 0.244 | O5: =IF(AND(L5="No",I5=0),"1: Critical (No DBWT + No Wk0)",IF(L5="No","2: High (No DBWT)",IF(I5=0,"3: Elevated (No Wk0)","4: Engaged Early"))) -> 2: High (No DBWT)
A6: Academy Intake X | B6: AIX10005 | C6: Yes | D6: 5 | E6: 5 | F6: 0 | G6: =IFERROR(E6/D6,0) -> 1 | H6: =IFERROR(F6/D6,0) -> 0 | I6: 0 | K6: 0.69 | L6: No | M6: 0 | N6: =ROUND(IFERROR(K6/100,0)*0.6 + IF(L6="Yes",1,IF(L6="No",0,0.3))*0.25 + IFERROR(J6/100,0)*0.15,3) -> 0.004 | O6: =IF(AND(L6="No",I6=0),"1: Critical (No DBWT + No Wk0)",IF(L6="No","2: High (No DBWT)",IF(I6=0,"3: Elevated (No Wk0)","4: Engaged Early"))) -> 1: Critical (No DBWT + No Wk0)
A7: Academy Intake X | B7: AIX10006 | C7: Yes | D7: 22 | E7: 8 | F7: 0 | G7: =IFERROR(E7/D7,0) -> 0.36363636 | H7: =IFERROR(F7/D7,0) -> 0 | I7: 2 | J7: 33.31315 | K7: 17.8 | L7: Yes | M7: 0 | N7: =ROUND(IFERROR(K7/100,0)*0.6 + IF(L7="Yes",1,IF(L7="No",0,0.3))*0.25 + IFERROR(J7/100,0)*0.15,3) -> 0.407 | O7: =IF(AND(L7="No",I7=0),"1: Critical (No DBWT + No Wk0)",IF(L7="No","2: High (No DBWT)",IF(I7=0,"3: Elevated (No Wk0)","4: Engaged Early"))) -> 4: Engaged Early
A8: Academy Intake X | B8: AIX10007 | C8: Yes | D8: 22 | E8: 20 | F8: 0 | G8: =IFERROR(E8/D8,0) -> 0.90909091 | H8: =IFERROR(F8/D8,0) -> 0 | I8: 0 | K8: 0 | L8: No | M8: 0 | N8: =ROUND(IFERROR(K8/100,0)*0.6 + IF(L8="Yes",1,IF(L8="No",0,0.3))*0.25 + IFERROR(J8/100,0)*0.15,3) -> 0 | O8: =IF(AND(L8="No",I8=0),"1: Critical (No DBWT + No Wk0)",IF(L8="No","2: High (No DBWT)",IF(I8=0,"3: Elevated (No Wk0)","4: Engaged Early"))) -> 1: Critical (No DBWT + No Wk0)
A9: Academy Intake X | B9: AIX10008 | C9: Yes | D9: 10 | E9: 9 | F9: 2 | G9: =IFERROR(E9/D9,0) -> 0.9 | H9: =IFERROR(F9/D9,0) -> 0.2 | I9: 2 | J9: 80.5078 | K9: 82.86 | L9: Yes | M9: 0 | N9: =ROUND(IFERROR(K9/100,0)*0.6 + IF(L9="Yes",1,IF(L9="No",0,0.3))*0.25 + IFERROR(J9/100,0)*0.15,3) -> 0.868 | O9: =IF(AND(L9="No",I9=0),"1: Critical (No DBWT + No Wk0)",IF(L9="No","2: High (No DBWT)",IF(I9=0,"3: Elevated (No Wk0)","4: Engaged Early"))) -> 4: Engaged Early
A10: Academy Intake X | B10: AIX10009 | C10: No | D10: 7 | E10: 7 | F10: 4 | G10: =IFERROR(E10/D10,0) -> 1 | H10: =IFERROR(F10/D10,0) -> 0.57142857 | I10: 0 | K10: 0 | L10: No | M10: 0 | N10: =ROUND(IFERROR(K10/100,0)*0.6 + IF(L10="Yes",1,IF(L10="No",0,0.3))*0.25 + IFERROR(J10/100,0)*0.15,3) -> 0 | O10: =IF(AND(L10="No",I10=0),"1: Critical (No DBWT + No Wk0)",IF(L10="No","2: High (No DBWT)",IF(I10=0,"3: Elevated (No Wk0)","4: Engaged Early"))) -> 1: Critical (No DBWT + No Wk0)
A11: Academy Intake X | B11: AIX10010 | C11: Yes | D11: 26 | E11: 22 | F11: 1 | G11: =IFERROR(E11/D11,0) -> 0.84615385 | H11: =IFERROR(F11/D11,0) -> 0.038461538 | I11: 0 | K11: 0 | L11: No | M11: 0 | N11: =ROUND(IFERROR(K11/100,0)*0.6 + IF(L11="Yes",1,IF(L11="No",0,0.3))*0.25 + IFERROR(J11/100,0)*0.15,3) -> 0 | O11: =IF(AND(L11="No",I11=0),"1: Critical (No DBWT + No Wk0)",IF(L11="No","2: High (No DBWT)",IF(I11=0,"3: Elevated (No Wk0)","4: Engaged Early"))) -> 1: Critical (No DBWT + No Wk0)
A12: Academy Intake X | B12: AIX10011 | C12: No | D12: 7 | E12: 5 | F12: 1 | G12: =IFERROR(E12/D12,0) -> 0.71428571 | H12: =IFERROR(F12/D12,0) -> 0.14285714 | I12: 1 | J12: 0.85 | K12: 0.12 | L12: No | M12: 0 | N12: =ROUND(IFERROR(K12/100,0)*0.6 + IF(L12="Yes",1,IF(L12="No",0,0.3))*0.25 + IFERROR(J12/100,0)*0.15,3) -> 0.002 | O12: =IF(AND(L12="No",I12=0),"1: Critical (No DBWT + No Wk0)",IF(L12="No","2: High (No DBWT)",IF(I12=0,"3: Elevated (No Wk0)","4: Engaged Early"))) -> 2: High (No DBWT)
A13: Academy Intake X | B13: AIX10012 | C13: Yes | D13: 21 | E13: 21 | F13: 2 | G13: =IFERROR(E13/D13,0) -> 1 | H13: =IFERROR(F13/D13,0) -> 0.095238095 | I13: 0 | K13: 0 | L13: No | M13: 0 | N13: =ROUND(IFERROR(K13/100,0)*0.6 + IF(L13="Yes",1,IF(L13="No",0,0.3))*0.25 + IFERROR(J13/100,0)*0.15,3) -> 0 | O13: =IF(AND(L13="No",I13=0),"1: Critical (No DBWT + No Wk0)",IF(L13="No","2: High (No DBWT)",IF(I13=0,"3: Elevated (No Wk0)","4: Engaged Early"))) -> 1: Critical (No DBWT + No Wk0)
A14: Academy Intake X | B14: AIX10013 | C14: No | D14: 23 | E14: 12 | F14: 2 | G14: =IFERROR(E14/D14,0) -> 0.52173913 | H14: =IFERROR(F14/D14,0) -> 0.086956522 | I14: 2 | J14: 93.05765 | K14: 98.38 | L14: Yes | M14: 0 | N14: =ROUND(IFERROR(K14/100,0)*0.6 + IF(L14="Yes",1,IF(L14="No",0,0.3))*0.25 + IFERROR(J14/100,0)*0.15,3) -> 0.98 | O14: =IF(AND(L14="No",I14=0),"1: Critical (No DBWT + No Wk0)",IF(L14="No","2: High (No DBWT)",IF(I14=0,"3: Elevated (No Wk0)","4: Engaged Early"))) -> 4: Engaged Early
A15: Academy Intake X | B15: AIX10014 | C15: Yes | D15: 24 | E15: 17 | F15: 0 | G15: =IFERROR(E15/D15,0) -> 0.70833333 | H15: =IFERROR(F15/D15,0) -> 0 | I15: 0 | K15: 0 | L15: No | M15: 0 | N15: =ROUND(IFERROR(K15/100,0)*0.6 + IF(L15="Yes",1,IF(L15="No",0,0.3))*0.25 + IFERROR(J15/100,0)*0.15,3) -> 0 | O15: =IF(AND(L15="No",I15=0),"1: Critical (No DBWT + No Wk0)",IF(L15="No","2: High (No DBWT)",IF(I15=0,"3: Elevated (No Wk0)","4: Engaged Early"))) -> 1: Critical (No DBWT + No Wk0)
A16: Academy Intake X | B16: AIX10015 | C16: No | D16: 13 | E16: 11 | F16: 3 | G16: =IFERROR(E16/D16,0) -> 0.84615385 | H16: =IFERROR(F16/D16,0) -> 0.23076923 | I16: 2 | J16: 87.17515 | K16: 97.37 | L16: Yes | M16: 0 | N16: =ROUND(IFERROR(K16/100,0)*0.6 + IF(L16="Yes",1,IF(L16="No",0,0.3))*0.25 + IFERROR(J16/100,0)*0.15,3) -> 0.965 | O16: =IF(AND(L16="No",I16=0),"1: Critical (No DBWT + No Wk0)",IF(L16="No","2: High (No DBWT)",IF(I16=0,"3: Elevated (No Wk0)","4: Engaged Early"))) -> 4: Engaged Early
A17: Academy Intake X | B17: AIX10016 | C17: No | D17: 20 | E17: 17 | F17: 1 | G17: =IFERROR(E17/D17,0) -> 0.85 | H17: =IFERROR(F17/D17,0) -> 0.05 | I17: 2 | J17: 64.68235 | K17: 42.89 | L17: Yes | M17: 0 | N17: =ROUND(IFERROR(K17/100,0)*0.6 + IF(L17="Yes",1,IF(L17="No",0,0.3))*0.25 + IFERROR(J17/100,0)*0.15,3) -> 0.604 | O17: =IF(AND(L17="No",I17=0),"1: Critical (No DBWT + No Wk0)",IF(L17="No","2: High (No DBWT)",IF(I17=0,"3: Elevated (No Wk0)","4: Engaged Early"))) -> 4: Engaged Early
A18: Academy Intake X | B18: AIX10017 | C18: No | D18: 13 | E18: 7 | F18: 1 | G18: =IFERROR(E18/D18,0) -> 0.53846154 | H18: =IFERROR(F18/D18,0) -> 0.076923077 | I18: 2 | J18: 94.81025 | K18: 57.26 | L18: Yes | M18: 0 | N18: =ROUND(IFERROR(K18/100,0)*0.6 + IF(L18="Yes",1,IF(L18="No",0,0.3))*0.25 + IFERROR(J18/100,0)*0.15,3) -> 0.736 | O18: =IF(AND(L18="No",I18=0),"1: Critical (No DBWT + No Wk0)",IF(L18="No","2: High (No DBWT)",IF(I18=0,"3: Elevated (No Wk0)","4: Engaged Early"))) -> 4: Engaged Early
A19: Academy Intake X | B19: AIX10018 | C19: Yes | D19: 23 | E19: 18 | F19: 0 | G19: =IFERROR(E19/D19,0) -> 0.7826087 | H19: =IFERROR(F19/D19,0) -> 0 | I19: 0 | K19: 0 | L19: No | M19: 0 | N19: =ROUND(IFERROR(K19/100,0)*0.6 + IF(L19="Yes",1,IF(L19="No",0,0.3))*0.25 + IFERROR(J19/100,0)*0.15,3) -> 0 | O19: =IF(AND(L19="No",I19=0),"1: Critical (No DBWT + No Wk0)",IF(L19="No","2: High (No DBWT)",IF(I19=0,"3: Elevated (No Wk0)","4: Engaged Early"))) -> 1: Critical (No DBWT + No Wk0)
A20: Academy Intake X | B20: AIX10019 | C20: Yes | D20: 6 | E20: 3 | F20: 0 | G20: =IFERROR(E20/D20,0) -> 0.5 | H20: =IFERROR(F20/D20,0) -> 0 | I20: 0 | K20: 0.05 | L20: Yes | M20: 0 | N20: =ROUND(IFERROR(K20/100,0)*0.6 + IF(L20="Yes",1,IF(L20="No",0,0.3))*0.25 + IFERROR(J20/100,0)*0.15,3) -> 0.25 | O20: =IF(AND(L20="No",I20=0),"1: Critical (No DBWT + No Wk0)",IF(L20="No","2: High (No DBWT)",IF(I20=0,"3: Elevated (No Wk0)","4: Engaged Early"))) -> 3: Elevated (No Wk0)
A21: Academy Intake X | B21: AIX10020 | C21: No | D21: 0 | E21: 0 | F21: 0 | G21: =IFERROR(E21/D21,0) -> 0 | H21: =IFERROR(F21/D21,0) -> 0 | I21: 0 | K21: 1.09 | L21: No | M21: 0 | N21: =ROUND(IFERROR(K21/100,0)*0.6 + IF(L21="Yes",1,IF(L21="No",0,0.3))*0.25 + IFERROR(J21/100,0)*0.15,3) -> 0.007 | O21: =IF(AND(L21="No",I21=0),"1: Critical (No DBWT + No Wk0)",IF(L21="No","2: High (No DBWT)",IF(I21=0,"3: Elevated (No Wk0)","4: Engaged Early"))) -> 1: Critical (No DBWT + No Wk0)
A22: Academy Intake X | B22: AIX10021 | C22: No | D22: 7 | E22: 2 | F22: 0 | G22: =IFERROR(E22/D22,0) -> 0.28571429 | H22: =IFERROR(F22/D22,0) -> 0 | I22: 2 | J22: 79.33595 | K22: 95.21 | L22: Yes | M22: 0 | N22: =ROUND(IFERROR(K22/100,0)*0.6 + IF(L22="Yes",1,IF(L22="No",0,0.3))*0.25 + IFERROR(J22/100,0)*0.15,3) -> 0.94 | O22: =IF(AND(L22="No",I22=0),"1: Critical (No DBWT + No Wk0)",IF(L22="No","2: High (No DBWT)",IF(I22=0,"3: Elevated (No Wk0)","4: Engaged Early"))) -> 4: Engaged Early
A23: Academy Intake X | B23: AIX10022 | C23: No | D23: 3 | E23: 2 | F23: 0 | G23: =IFERROR(E23/D23,0) -> 0.66666667 | H23: =IFERROR(F23/D23,0) -> 0 | I23: 1 | J23: 34.46 | K23: 10.37 | L23: Yes | M23: 0 | N23: =ROUND(IFERROR(K23/100,0)*0.6 + IF(L23="Yes",1,IF(L23="No",0,0.3))*0.25 + IFERROR(J23/100,0)*0.15,3) -> 0.364 | O23: =IF(AND(L23="No",I23=0),"1: Critical (No DBWT + No Wk0)",IF(L23="No","2: High (No DBWT)",IF(I23=0,"3: Elevated (No Wk0)","4: Engaged Early"))) -> 4: Engaged Early
A24: Academy Intake X | B24: AIX10023 | C24: No | D24: 21 | E24: 18 | F24: 6 | G24: =IFERROR(E24/D24,0) -> 0.85714286 | H24: =IFERROR(F24/D24,0) -> 0.28571429 | I24: 2 | J24: 97.27395 | K24: 88.89 | L24: Yes | M24: 0 | N24: =ROUND(IFERROR(K24/100,0)*0.6 + IF(L24="Yes",1,IF(L24="No",0,0.3))*0.25 + IFERROR(J24/100,0)*0.15,3) -> 0.929 | O24: =IF(AND(L24="No",I24=0),"1: Critical (No DBWT + No Wk0)",IF(L24="No","2: High (No DBWT)",IF(I24=0,"3: Elevated (No Wk0)","4: Engaged Early"))) -> 4: Engaged Early
A25: Academy Intake X | B25: AIX10024 | C25: No | D25: 5 | E25: 5 | F25: 0 | G25: =IFERROR(E25/D25,0) -> 1 | H25: =IFERROR(F25/D25,0) -> 0 | I25: 0 | K25: 0 | L25: No | M25: 0 | N25: =ROUND(IFERROR(K25/100,0)*0.6 + IF(L25="Yes",1,IF(L25="No",0,0.3))*0.25 + IFERROR(J25/100,0)*0.15,3) -> 0 | O25: =IF(AND(L25="No",I25=0),"1: Critical (No DBWT + No Wk0)",IF(L25="No","2: High (No DBWT)",IF(I25=0,"3: Elevated (No Wk0)","4: Engaged Early"))) -> 1: Critical (No DBWT + No Wk0)
A26: Academy Intake X | B26: AIX10025 | C26: No | D26: 0 | E26: 0 | F26: 0 | G26: =IFERROR(E26/D26,0) -> 0 | H26: =IFERROR(F26/D26,0) -> 0 | I26: 0 | K26: 49.93 | L26: Not Tracked | M26: 0 | N26: =ROUND(IFERROR(K26/100,0)*0.6 + IF(L26="Yes",1,IF(L26="No",0,0.3))*0.25 + IFERROR(J26/100,0)*0.15,3) -> 0.375 | O26: =IF(AND(L26="No",I26=0),"1: Critical (No DBWT + No Wk0)",IF(L26="No","2: High (No DBWT)",IF(I26=0,"3: Elevated (No Wk0)","4: Engaged Early"))) -> 3: Elevated (No Wk0)
A27: Academy Intake X | B27: AIX10026 | C27: No | D27: 23 | E27: 22 | F27: 3 | G27: =IFERROR(E27/D27,0) -> 0.95652174 | H27: =IFERROR(F27/D27,0) -> 0.13043478 | I27: 2 | J27: 48.30066 | K27: 82.13 | L27: Yes | M27: 0 | N27: =ROUND(IFERROR(K27/100,0)*0.6 + IF(L27="Yes",1,IF(L27="No",0,0.3))*0.25 + IFERROR(J27/100,0)*0.15,3) -> 0.815 | O27: =IF(AND(L27="No",I27=0),"1: Critical (No DBWT + No Wk0)",IF(L27="No","2: High (No DBWT)",IF(I27=0,"3: Elevated (No Wk0)","4: Engaged Early"))) -> 4: Engaged Early
A28: Academy Intake X | B28: AIX10027 | C28: No | D28: 10 | E28: 6 | F28: 0 | G28: =IFERROR(E28/D28,0) -> 0.6 | H28: =IFERROR(F28/D28,0) -> 0 | I28: 1 | J28: 9.8751 | K28: 12.58 | L28: Yes | M28: 0 | N28: =ROUND(IFERROR(K28/100,0)*0.6 + IF(L28="Yes",1,IF(L28="No",0,0.3))*0.25 + IFERROR(J28/100,0)*0.15,3) -> 0.34 | O28: =IF(AND(L28="No",I28=0),"1: Critical (No DBWT + No Wk0)",IF(L28="No","2: High (No DBWT)",IF(I28=0,"3: Elevated (No Wk0)","4: Engaged Early"))) -> 4: Engaged Early
A29: Academy Intake X | B29: AIX10028 | C29: No | D29: 13 | E29: 8 | F29: 2 | G29: =IFERROR(E29/D29,0) -> 0.61538462 | H29: =IFERROR(F29/D29,0) -> 0.15384615 | I29: 2 | J29: 94.445 | K29: 100 | L29: Yes | M29: 0 | N29: =ROUND(IFERROR(K29/100,0)*0.6 + IF(L29="Yes",1,IF(L29="No",0,0.3))*0.25 + IFERROR(J29/100,0)*0.15,3) -> 0.992 | O29: =IF(AND(L29="No",I29=0),"1: Critical (No DBWT + No Wk0)",IF(L29="No","2: High (No DBWT)",IF(I29=0,"3: Elevated (No Wk0)","4: Engaged Early"))) -> 4: Engaged Early
A30: Academy Intake X | B30: AIX10029 | C30: Yes | D30: 10 | E30: 10 | F30: 3 | G30: =IFERROR(E30/D30,0) -> 1 | H30: =IFERROR(F30/D30,0) -> 0.3 | I30: 1 | J30: 7.02 | K30: 9.39 | L30: No | M30: 0 | N30: =ROUND(IFERROR(K30/100,0)*0.6 + IF(L30="Yes",1,IF(L30="No",0,0.3))*0.25 + IFERROR(J30/100,0)*0.15,3) -> 0.067 | O30: =IF(AND(L30="No",I30=0),"1: Critical (No DBWT + No Wk0)",IF(L30="No","2: High (No DBWT)",IF(I30=0,"3: Elevated (No Wk0)","4: Engaged Early"))) -> 2: High (No DBWT)
A31: Academy Intake X | B31: AIX10030 | C31: No | D31: 10 | E31: 8 | F31: 2 | G31: =IFERROR(E31/D31,0) -> 0.8 | H31: =IFERROR(F31/D31,0) -> 0.2 | I31: 2 | J31: 99.84665 | K31: 94.24 | L31: Yes | M31: 0 | N31: =ROUND(IFERROR(K31/100,0)*0.6 + IF(L31="Yes",1,IF(L31="No",0,0.3))*0.25 + IFERROR(J31/100,0)*0.15,3) -> 0.965 | O31: =IF(AND(L31="No",I31=0),"1: Critical (No DBWT + No Wk0)",IF(L31="No","2: High (No DBWT)",IF(I31=0,"3: Elevated (No Wk0)","4: Engaged Early"))) -> 4: Engaged Early
A32: Academy Intake X | B32: AIX10031 | C32: Yes | D32: 3 | E32: 3 | F32: 0 | G32: =IFERROR(E32/D32,0) -> 1 | H32: =IFERROR(F32/D32,0) -> 0 | I32: 0 | K32: 0 | L32: No | M32: 0 | N32: =ROUND(IFERROR(K32/100,0)*0.6 + IF(L32="Yes",1,IF(L32="No",0,0.3))*0.25 + IFERROR(J32/100,0)*0.15,3) -> 0 | O32: =IF(AND(L32="No",I32=0),"1: Critical (No DBWT + No Wk0)",IF(L32="No","2: High (No DBWT)",IF(I32=0,"3: Elevated (No Wk0)","4: Engaged Early"))) -> 1: Critical (No DBWT + No Wk0)
A33: Academy Intake X | B33: AIX10032 | C33: No | D33: 13 | E33: 1 | F33: 0 | G33: =IFERROR(E33/D33,0) -> 0.076923077 | H33: =IFERROR(F33/D33,0) -> 0 | I33: 2 | J33: 99.75255 | K33: 100 | L33: Yes | M33: 0 | N33: =ROUND(IFERROR(K33/100,0)*0.6 + IF(L33="Yes",1,IF(L33="No",0,0.3))*0.25 + IFERROR(J33/100,0)*0.15,3) -> 1 | O33: =IF(AND(L33="No",I33=0),"1: Critical (No DBWT + No Wk0)",IF(L33="No","2: High (No DBWT)",IF(I33=0,"3: Elevated (No Wk0)","4: Engaged Early"))) -> 4: Engaged Early
A34: Academy Intake X | B34: AIX10033 | C34: Yes | D34: 13 | E34: 0 | F34: 0 | G34: =IFERROR(E34/D34,0) -> 0 | H34: =IFERROR(F34/D34,0) -> 0 | I34: 2 | J34: 68.11475 | K34: 16.84 | L34: Yes | M34: 0 | N34: =ROUND(IFERROR(K34/100,0)*0.6 + IF(L34="Yes",1,IF(L34="No",0,0.3))*0.25 + IFERROR(J34/100,0)*0.15,3) -> 0.453 | O34: =IF(AND(L34="No",I34=0),"1: Critical (No DBWT + No Wk0)",IF(L34="No","2: High (No DBWT)",IF(I34=0,"3: Elevated (No Wk0)","4: Engaged Early"))) -> 4: Engaged Early
A35: Academy Intake X | B35: AIX10034 | C35: No | D35: 15 | E35: 9 | F35: 1 | G35: =IFERROR(E35/D35,0) -> 0.6 | H35: =IFERROR(F35/D35,0) -> 0.066666667 | I35: 2 | J35: 88.03625 | K35: 100 | L35: Yes | M35: 0 | N35: =ROUND(IFERROR(K35/100,0)*0.6 + IF(L35="Yes",1,IF(L35="No",0,0.3))*0.25 + IFERROR(J35/100,0)*0.15,3) -> 0.982 | O35: =IF(AND(L35="No",I35=0),"1: Critical (No DBWT + No Wk0)",IF(L35="No","2: High (No DBWT)",IF(I35=0,"3: Elevated (No Wk0)","4: Engaged Early"))) -> 4: Engaged Early
A36: Academy Intake X | B36: AIX10035 | C36: No | D36: 22 | E36: 12 | F36: 1 | G36: =IFERROR(E36/D36,0) -> 0.54545455 | H36: =IFERROR(F36/D36,0) -> 0.045454545 | I36: 2 | J36: 85.01325 | K36: 34.52 | L36: Yes | M36: 0 | N36: =ROUND(IFERROR(K36/100,0)*0.6 + IF(L36="Yes",1,IF(L36="No",0,0.3))*0.25 + IFERROR(J36/100,0)*0.15,3) -> 0.585 | O36: =IF(AND(L36="No",I36=0),"1: Critical (No DBWT + No Wk0)",IF(L36="No","2: High (No DBWT)",IF(I36=0,"3: Elevated (No Wk0)","4: Engaged Early"))) -> 4: Engaged Early
A37: Academy Intake X | B37: AIX10036 | C37: No | D37: 17 | E37: 5 | F37: 0 | G37: =IFERROR(E37/D37,0) -> 0.29411765 | H37: =IFERROR(F37/D37,0) -> 0 | I37: 2 | J37: 94.79165 | K37: 100 | L37: Yes | M37: 0 | N37: =ROUND(IFERROR(K37/100,0)*0.6 + IF(L37="Yes",1,IF(L37="No",0,0.3))*0.25 + IFERROR(J37/100,0)*0.15,3) -> 0.992 | O37: =IF(AND(L37="No",I37=0),"1: Critical (No DBWT + No Wk0)",IF(L37="No","2: High (No DBWT)",IF(I37=0,"3: Elevated (No Wk0)","4: Engaged Early"))) -> 4: Engaged Early
A38: Academy Intake X | B38: AIX10037 | C38: Yes | D38: 4 | E38: 4 | F38: 2 | G38: =IFERROR(E38/D38,0) -> 1 | H38: =IFERROR(F38/D38,0) -> 0.5 | I38: 1 | J38: 38.61 | K38: 9.65 | L38: Yes | M38: 0 | N38: =ROUND(IFERROR(K38/100,0)*0.6 + IF(L38="Yes",1,IF(L38="No",0,0.3))*0.25 + IFERROR(J38/100,0)*0.15,3) -> 0.366 | O38: =IF(AND(L38="No",I38=0),"1: Critical (No DBWT + No Wk0)",IF(L38="No","2: High (No DBWT)",IF(I38=0,"3: Elevated (No Wk0)","4: Engaged Early"))) -> 4: Engaged Early
A39: Academy Intake X | B39: AIX10038 | C39: Yes | D39: 15 | E39: 10 | F39: 0 | G39: =IFERROR(E39/D39,0) -> 0.66666667 | H39: =IFERROR(F39/D39,0) -> 0 | I39: 0 | K39: 0 | L39: Yes | M39: 0 | N39: =ROUND(IFERROR(K39/100,0)*0.6 + IF(L39="Yes",1,IF(L39="No",0,0.3))*0.25 + IFERROR(J39/100,0)*0.15,3) -> 0.25 | O39: =IF(AND(L39="No",I39=0),"1: Critical (No DBWT + No Wk0)",IF(L39="No","2: High (No DBWT)",IF(I39=0,"3: Elevated (No Wk0)","4: Engaged Early"))) -> 3: Elevated (No Wk0)
A40: Academy Intake X | B40: AIX10039 | C40: No | D40: 13 | E40: 7 | F40: 1 | G40: =IFERROR(E40/D40,0) -> 0.53846154 | H40: =IFERROR(F40/D40,0) -> 0.076923077 | I40: 1 | J40: 63.56 | K40: 53.3 | L40: Yes | M40: 0 | N40: =ROUND(IFERROR(K40/100,0)*0.6 + IF(L40="Yes",1,IF(L40="No",0,0.3))*0.25 + IFERROR(J40/100,0)*0.15,3) -> 0.665 | O40: =IF(AND(L40="No",I40=0),"1: Critical (No DBWT + No Wk0)",IF(L40="No","2: High (No DBWT)",IF(I40=0,"3: Elevated (No Wk0)","4: Engaged Early"))) -> 4: Engaged Early
...

Sheet Learner IDs
A1: Batch | B1: Learner ID | C1: Refunded?
A2: Academy Intake X | B2: AIX10001 | C2: Yes
A3: Academy Intake X | B3: AIX10002 | C3: Yes
A4: Academy Intake X | B4: AIX10003 | C4: No
A5: Academy Intake X | B5: AIX10004 | C5: Yes
A6: Academy Intake X | B6: AIX10005 | C6: Yes
A7: Academy Intake X | B7: AIX10006 | C7: Yes
A8: Academy Intake X | B8: AIX10007 | C8: Yes
A9: Academy Intake X | B9: AIX10008 | C9: Yes
A10: Academy Intake X | B10: AIX10009 | C10: No
A11: Academy Intake X | B11: AIX10010 | C11: Yes
A12: Academy Intake X | B12: AIX10011 | C12: No
... A1650: Academy Intake X | B1650: AIX11649 | C1650: No

Sheet Comms Tracker
A1: Learner ID | B1: Delivered | C1: Opened / Read | D1: Clicked | E1: Week
A2: AIX10383 | B2: 5 | C2: 1 | D2: 0 | E2: T-1
A3: AIX10698 | B3: 5 | C3: 4 | D3: 1 | E3: T-1
A4: AIX11027 | B4: 5 | C4: 5 | D4: 0 | E4: T-1
A5: AIX10428 | B5: 6 | C5: 6 | D5: 0 | E5: T-2
A6: AIX11388 | B6: 3 | C6: 1 | D6: 0 | E6: T-3
A7: AIX10642 | B7: 5 | C7: 2 | D7: 0 | E7: T-1
A8: AIX10255 | B8: 8 | C8: 5 | D8: 2 | E8: T-1
A9: AIX10132 | B9: 2 | C9: 1 | D9: 0 | E9: T-1
A10: AIX10002 | B10: 2 | C10: 2 | D10: 1 | E10: T-1
A11: AIX10061 | B11: 8 | C11: 7 | D11: 3 | E11: T-1
A12: AIX10374 | B12: 8 | C12: 7 | D12: 2 | E12: T-1
A13: AIX10439 | B13: 8 | C13: 7 | D13: 3 | E13: T-1
... A1541: AIX11318 | B1541: 24 | C1541: 20 | D1541: 0 | E1541: T-4

Sheet Week 0 Attendance
A1: Learner ID | B1: meeting slug | C1: attendance | D1: live_attendance | E1: passive_attendance
A2: AIX10066 | B2: build-the-problem-solving-mindset | C2: 100 | D2: 99.8168 | E2: 13.8077
A3: AIX10574 | B3: build-the-problem-solving-mindset | C3: 100 | D3: 16.9692 | E3: 99.7177
A4: AIX10362 | B4: build-the-problem-solving-mindset | C4: 100 | D4: 100
A5: AIX10386 | B5: build-the-problem-solving-mindset | C5: 100 | D5: 39.9417 | E5: 59.9718
A6: AIX10280 | B6: build-the-problem-solving-mindset | C6: 100 | D6: 100
A7: AIX11090 | B7: build-the-problem-solving-mindset | C7: 100 | D7: 84.9042 | E7: 97.0027
A8: AIX10028 | B8: build-the-problem-solving-mindset | C8: 100 | D8: 47.4938 | E8: 99.7758
A9: AIX10581 | B9: build-the-problem-solving-mindset | C9: 100 | D9: 99.7002 | E9: 14.4221
A10: AIX10175 | B10: build-the-problem-solving-mindset | C10: 100 | E10: 100.058
A11: AIX10392 | B11: build-the-problem-solving-mindset | C11: 100 | D11: 99.6753 | E11: 100.058
A12: AIX11084 | B12: build-the-problem-solving-mindset | C12: 100 | D12: 60.7744 | E12: 76.7187
A13: AIX10309 | B13: build-the-problem-solving-mindset | C13: 100 | E13: 100.058
A14: AIX10030 | B14: build-the-problem-solving-mindset | C14: 99.9833 | D14: 99.9833
A15: AIX11262 | B15: build-the-problem-solving-mindset | C15: 99.95 | D15: 97.7186 | E15: 20.7904
A16: AIX10356 | B16: build-the-problem-solving-mindset | C16: 99.95 | D16: 95.2623 | E16: 76.5028
