Workbook

Sheet 1.Approach
A1: SECI Assured Peak Supply (APS) under CfD — Solar + BESS Bid Model
A2: 100 MW contract | 3-hour evening peak | Solar PV + Battery hybrid | Target Project IRR 12%
A5: OBJECTIVE
B6: Size a Solar + BESS portfolio to firmly deliver 100 MW for 3 hours in the evening peak, find the minimum
B7: CfD strike price that earns a 12% project IRR, value the merchant surplus on 3-yr IEX DAM prices, and
B8: test the sensitivity of equity returns and pool cost to a +/-10% move in market prices.
A10: HOW THE MODEL WORKS (5 steps)
A11: Step 1 - Size BESS | B11: Fixed by the contract: 100 MW power, 4-hour product (400 MWh nameplate). After 87% round-trip
B12: efficiency it comfortably delivers the 300 MWh needed in the 3h peak, with headroom for degradation.
A13: Step 2 - Size Solar | B13: Set by the reliability of charging the battery every day, NOT by merchant economics. At IEX midday
B14: prices (~Rs 3/kWh) extra solar is roughly value-neutral, so we build the minimum overbuild that assures
B15: charging across seasons: 1.5x = 150 MW. The strike penalty vs a 1.0x build is only ~Rs 0.1/kWh (see 3.Sizing).
A16: Step 3 - Energy balance | B16: Solar first charges the battery (300/0.87 = 345 MWh/day); the surplus is sold merchant in the day.
A17: Step 4 - Solve strike | B17: Build a 25-yr post-tax unlevered cash flow. Peak energy earns the strike; surplus earns the DAM day price.
B18: Goal-seek the strike so Project IRR = 12% (see 4.Cashflow). Result ~ Rs 10.8/kWh.
A19: Step 5 - Sensitivity | B19: Layer 70:30 debt for Equity IRR, then flex market price +/-10% to see impact on EIRR and pool cost (6.Sensitivity).
A21: CfD SETTLEMENT LOGIC
B22: Two-way CfD on the 300 MWh/day peak block. If DAM peak price < strike, SECI tops the developer up to strike.
B23: If DAM peak price > strike, the gain above strike is shared 50:50. Merchant day-surplus is 100% the developer's.
A25: KEY RESULTS
A26: Recommended sizing | B26: Solar 150 MW + BESS 100 MW / 4h (400 MWh) | Total capex Rs 950 Cr
A27: Required strike price | B27: ~ Rs 10.8 / kWh (12% post-tax project IRR, straight-line depreciation)
A28: Equity IRR (70:30 debt) | B28: ~ 17.4%
A29: Sensitivity (+/-10% price) | B29: EIRR moves to 18.4% / 16.3% ; SECI pool top-up moves to 46 / 59 Cr per year
A31: READ ME | B31: Blue cells = inputs you can change. Black = formulas. Green = links to other tabs. Yellow = key levers.
B32: All assumptions and sources are on tab 2.Assumptions. Change an input and re-open to recalc.

Sheet 2.Assumptions
A1: ASSUMPTIONS (blue = input)
A2: Parameter | B2: Value | C2: Unit | D2: Rationale / Source
A3: CONTRACT & TECHNICAL
A4: Contract capacity | B4: 100 | C4: MW | D4: SECI APS tender requirement (given in brief)
A5: Peak supply duration | B5: 3 | C5: hours | D5: Tender: 3h assured peak window
A6: Peak window | B6: 18:00-21:00 | D6: Assumption: evening demand peak; solar absent so needs BESS; highest DAM prices. Ref: SECI FDRE/peak RfS peak-hour definition
A7: Peak energy delivered/day | B7: =B4*B5 -> 300 | C7: MWh | D7: capacity x hours = 300 MWh
A8: Days per year | B8: 365 | C8: days | D8: Assumed 100% peak availability (assured-supply obligation)
A9: SOLAR
A10: Solar capacity (chosen) | B10: 150 | C10: MW | D10: Recommended 1.5x overbuild for reliable daily charging (see 3.Sizing). INPUT you can flex.
A11: Solar CUF | B11: 0.21 | C11: ratio | D11: Typical Indian utility solar 19-22%. Assumption 21%. Ref: CERC/MNRE benchmark, historical plant data
A12: Solar degradation | B12: 0.005 | C12: /yr | D12: 0.5%/yr module degradation - industry standard (mfr warranties)
A13: Solar capex | B13: 4 | C13: Rs Cr/MW | D13: Given in brief (key input 1)
A14: BESS
A15: BESS power (chosen) | B15: 100 | C15: MW | D15: contract power; must deliver 100 MW in peak
A16: BESS duration (product) | B16: 4 | C16: hours | D16: Capex quoted for 4h product; 4h gives headroom over 3h need
A17: BESS round-trip efficiency | B17: 0.87 | C17: ratio | D17: Li-ion RTE ~85-90%. Assumption 87%. Ref: NREL/BNEF storage data
A18: BESS capex (4h) | B18: 3.5 | C18: Rs Cr/MW | D18: Given in brief (key input 2). Includes augmentation reserve via O&M
A19: Energy to charge/day | B19: =B7/B17 -> 344.82759 | C19: MWh | D19: 300 / RTE = 345 MWh (AC into battery)
A20: MARKET PRICES (IEX DAM, 3-yr indicative)
A21: DAM peak-hour price | B21: 6 | C21: Rs/kWh | D21: 3-yr avg evening-peak DAM. Ref: IEX Day-Ahead Market MCP FY22-FY24 (iexindia.com). INDICATIVE - replace with downloaded 18-21h data
A22: DAM solar-hour price | B22: 3 | C22: Rs/kWh | D22: 3-yr avg midday DAM (solar depresses prices). Ref: IEX DAM MCP FY22-FY24. INDICATIVE - replace with 10-16h data
A23: Merchant price escalation | B23: 0.03 | C23: /yr | D23: Assumption 3%/yr nominal, below general inflation (RE glut caps day prices)
A24: OPERATING & FINANCIAL
A25: Solar O&M (% capex, yr1) | B25: 0.01 | C25: /yr | D25: 1.0% of solar capex. Ref: CERC RE tariff O&M norms
A26: BESS O&M (% capex, yr1) | B26: 0.025 | C26: /yr | D26: 2.5% - higher, includes battery augmentation reserve for capacity fade
A27: O&M escalation | B27: 0.05 | C27: /yr | D27: 5.0%/yr - CERC standard O&M escalation
A28: Project life | B28: 25 | C28: years | D28: Standard solar PPA/asset life; battery augmented to match
A29: Target project IRR | B29: 0.12 | C29: ratio | D29: Given in brief (post-tax, unlevered)
A30: Corporate tax rate | B30: 0.25 | C30: ratio | D30: ~25% (concessional 22% + surcharge/cess). Simplified. Ref: Income Tax Act sec 115BAA
A31: Depreciation method | B31: Straight-line | D31: SL over 25y for tax (simple/conservative). Note: accelerated dep would lower strike ~Rs 0.6
A32: FINANCING (for Equity IRR)
A33: Debt : Equity | B33: 0.7 | C33: debt frac | D33: 70:30 typical RE project finance
A34: Interest rate | B34: 0.09 | C34: /yr | D34: 9% INR term debt (indicative)
A35: Debt tenor | B35: 15 | C35: years | D35: 15-yr amortisation, equal principal
A36: Gain-share above strike | B36: 0.5 | C36: dev share | D36: Developer keeps 50% of upside above strike (assumption; confirm vs tender RfS)

Sheet 3.Sizing
A1: SIZING LOGIC & ENERGY BALANCE
A3: A. Energy balance (annual, year 1)
A4: Solar generation, yr1 | B4: ='2.Assumptions'!$B$10*8760*'2.Assumptions'!$B$11 -> 275940 | C4: MWh | D4: MW x 8760 x CUF
A5: Energy needed to charge BESS | B5: ='2.Assumptions'!$B$19*'2.Assumptions'!$B$8 -> 125862.07 | C5: MWh | D5: ~345 MWh/day x 365
A6: Merchant surplus (day sales) | B6: =B4-B5 -> 150077.93 | C6: MWh | D6: solar gen - charging
A7: Peak energy delivered (CfD) | B7: ='2.Assumptions'!$B$7*'2.Assumptions'!$B$8 -> 109500 | C7: MWh | D7: 300 x 365
A10: B. CAPEX
A11: Solar capex | B11: ='2.Assumptions'!$B$10*'2.Assumptions'!$B$13 -> 600 | C11: Rs Cr
A12: BESS capex | B12: ='2.Assumptions'!$B$15*'2.Assumptions'!$B$18 -> 350 | C12: Rs Cr
A13: Total capex | B13: =B11+B12 -> 950 | C13: Rs Cr
A15: C. Why 150 MW solar? (strike vs overbuild - illustrative, from model)
A16: Solar MW | B16: Overbuild | C16: Merchant GWh | D16: Strike Rs/kWh | E16: Assured supply?
A17: 100 | B17: 1.0x | C17: 58 | D17: 10.69 | E17: Tight - fails on cloudy days
A18: 120 | B18: 1.2x | C18: 95 | D18: 10.74 | E18: Marginal
A19: 150 | B19: 1.5x | C19: 150 | D19: 10.81 | E19: ROBUST <-- chosen
A20: 180 | B20: 1.8x | C20: 205 | D20: 10.88 | E20: Robust but excess capex
A21: 220 | B21: 2.2x | C21: 279 | D21: 10.98 | E21: Over-exposed to merchant
A23: Takeaway: strike is nearly flat vs overbuild (merchant is ~value-neutral at Rs 3/kWh),
A24: so solar size is driven by charging RELIABILITY. 1.5x assures the peak obligation at only ~Rs 0.1/kWh premium.

Sheet 4.Cashflow
A1: UNLEVERED CASH FLOW -> SOLVE STRIKE FOR 12% PROJECT IRR
A2: Strike (Rs/kWh): | B2: 10.81 | C2: <- goal-seek: change until Project IRR (B3) = 12.0%
A3: Project IRR (target 12.0%) | B3: =IRR(C20:AB20) -> 0.11999334
A4: Project NPV @ 12% (Rs Cr) | B4: =NPV('2.Assumptions'!$B$30*0+0.12,D20:AB20)+C20 -> -0.043740403
A6: Line item (Rs Cr unless noted) | B6: Unit | C6: 0 | D6: 1 | E6: 2 | F6: 3 | G6: 4 | H6: 5 | I6: 6 | J6: 7 | K6: 8 | L6: 9 | M6: 10 | N6: 11 | O6: 12 | P6: 13 | Q6: 14 | R6: 15 | S6: 16 | T6: 17 | U6: 18 | V6: 19 | W6: 20 | X6: 21 | Y6: 22 | Z6: 23 | AA6: 24 | AB6: 25
A7: Solar generation | B7: MWh | C7: 0 | D7: ='3.Sizing'!$B$4*(1-'2.Assumptions'!$B$12)^(1-1) -> 275940 | E7: ='3.Sizing'!$B$4*(1-'2.Assumptions'!$B$12)^(2-1) -> 274560.3 | F7: ='3.Sizing'!$B$4*(1-'2.Assumptions'!$B$12)^(3-1) -> 273187.5 | G7: ='3.Sizing'!$B$4*(1-'2.Assumptions'!$B$12)^(4-1) -> 271821.56 | H7: ='3.Sizing'!$B$4*(1-'2.Assumptions'!$B$12)^(5-1) -> 270462.45 | I7: ='3.Sizing'!$B$4*(1-'2.Assumptions'!$B$12)^(6-1) -> 269110.14 | J7: ='3.Sizing'!$B$4*(1-'2.Assumptions'!$B$12)^(7-1) -> 267764.59 | K7: ='3.Sizing'!$B$4*(1-'2.Assumptions'!$B$12)^(8-1) -> 266425.77 | L7: ='3.Sizing'!$B$4*(1-'2.Assumptions'!$B$12)^(9-1) -> 265093.64 | M7: ='3.Sizing'!$B$4*(1-'2.Assumptions'!$B$12)^(10-1) -> 263768.17 | N7: ='3.Sizing'!$B$4*(1-'2.Assumptions'!$B$12)^(11-1) -> 262449.33 | O7: ='3.Sizing'!$B$4*(1-'2.Assumptions'!$B$12)^(12-1) -> 261137.08 | P7: ='3.Sizing'!$B$4*(1-'2.Assumptions'!$B$12)^(13-1) -> 259831.4 | Q7: ='3.Sizing'!$B$4*(1-'2.Assumptions'!$B$12)^(14-1) -> 258532.24 | R7: ='3.Sizing'!$B$4*(1-'2.Assumptions'!$B$12)^(15-1) -> 257239.58 | S7: ='3.Sizing'!$B$4*(1-'2.Assumptions'!$B$12)^(16-1) -> 255953.38 | T7: ='3.Sizing'!$B$4*(1-'2.Assumptions'!$B$12)^(17-1) -> 254673.61 | U7: ='3.Sizing'!$B$4*(1-'2.Assumptions'!$B$12)^(18-1) -> 253400.25 | V7: ='3.Sizing'!$B$4*(1-'2.Assumptions'!$B$12)^(19-1) -> 252133.25 | W7: ='3.Sizing'!$B$4*(1-'2.Assumptions'!$B$12)^(20-1) -> 250872.58 | X7: ='3.Sizing'!$B$4*(1-'2.Assumptions'!$B$12)^(21-1) -> 249618.22 | Y7: ='3.Sizing'!$B$4*(1-'2.Assumptions'!$B$12)^(22-1) -> 248370.12 | Z7: ='3.Sizing'!$B$4*(1-'2.Assumptions'!$B$12)^(23-1) -> 247128.27 | AA7: ='3.Sizing'!$B$4*(1-'2.Assumptions'!$B$12)^(24-1) -> 245892.63 | AB7: ='3.Sizing'!$B$4*(1-'2.Assumptions'!$B$12)^(25-1) -> 244663.17
A8: Merchant surplus | B8: MWh | C8: 0 | D8: =MAX(D7-'3.Sizing'!$B$5,0) -> 150077.93 | E8: =MAX(E7-'3.Sizing'!$B$5,0) -> 148698.23 | F8: =MAX(F7-'3.Sizing'!$B$5,0) -> 147325.43 | G8: =MAX(G7-'3.Sizing'!$B$5,0) -> 145959.49 | H8: =MAX(H7-'3.Sizing'!$B$5,0) -> 144600.38 | I8: =MAX(I7-'3.Sizing'!$B$5,0) -> 143248.07 | J8: =MAX(J7-'3.Sizing'!$B$5,0) -> 141902.52 | K8: =MAX(K7-'3.Sizing'!$B$5,0) -> 140563.7 | ... AB8: =MAX(AB7-'3.Sizing'!$B$5,0) -> 118801.1
A9: Peak delivered | B9: MWh | C9: 0 | D9: ='3.Sizing'!$B$7 -> 109500 | E9: ='3.Sizing'!$B$7 -> 109500 | F9: ='3.Sizing'!$B$7 -> 109500 | G9: ='3.Sizing'!$B$7 -> 109500 | H9: ='3.Sizing'!$B$7 -> 109500 | I9: ='3.Sizing'!$B$7 -> 109500 | J9: ='3.Sizing'!$B$7 -> 109500 | K9: ='3.Sizing'!$B$7 -> 109500 | ... AB9: ='3.Sizing'!$B$7 -> 109500
A10: Merchant price | B10: Rs/kWh | D10: ='2.Assumptions'!$B$22*(1+'2.Assumptions'!$B$23)^(1-1) -> 3 | E10: ='2.Assumptions'!$B$22*(1+'2.Assumptions'!$B$23)^(2-1) -> 3.09 | F10: ='2.Assumptions'!$B$22*(1+'2.Assumptions'!$B$23)^(3-1) -> 3.1827 | G10: ='2.Assumptions'!$B$22*(1+'2.Assumptions'!$B$23)^(4-1) -> 3.278181 | H10: ='2.Assumptions'!$B$22*(1+'2.Assumptions'!$B$23)^(5-1) -> 3.3765264 | I10: ='2.Assumptions'!$B$22*(1+'2.Assumptions'!$B$23)^(6-1) -> 3.4778222 | J10: ='2.Assumptions'!$B$22*(1+'2.Assumptions'!$B$23)^(7-1) -> 3.5821569 | K10: ='2.Assumptions'!$B$22*(1+'2.Assumptions'!$B$23)^(8-1) -> 3.6896216 | L10: ='2.Assumptions'!$B$22*(1+'2.Assumptions'!$B$23)^(9-1) -> 3.8003102 | M10: ='2.Assumptions'!$B$22*(1+'2.Assumptions'!$B$23)^(10-1) -> 3.9143196 | N10: ='2.Assumptions'!$B$22*(1+'2.Assumptions'!$B$23)^(11-1) -> 4.0317491 | O10: ='2.Assumptions'!$B$22*(1+'2.Assumptions'!$B$23)^(12-1) -> 4.1527016 | P10: ='2.Assumptions'!$B$22*(1+'2.Assumptions'!$B$23)^(13-1) -> 4.2772827 | Q10: ='2.Assumptions'!$B$22*(1+'2.Assumptions'!$B$23)^(14-1) -> 4.4056011 | R10: ='2.Assumptions'!$B$22*(1+'2.Assumptions'!$B$23)^(15-1) -> 4.5377692 | S10: ='2.Assumptions'!$B$22*(1+'2.Assumptions'!$B$23)^(16-1) -> 4.6739022 | T10: ='2.Assumptions'!$B$22*(1+'2.Assumptions'!$B$23)^(17-1) -> 4.8141193 | U10: ='2.Assumptions'!$B$22*(1+'2.Assumptions'!$B$23)^(18-1) -> 4.9585429 | V10: ='2.Assumptions'!$B$22*(1+'2.Assumptions'!$B$23)^(19-1) -> 5.1072992 | W10: ='2.Assumptions'!$B$22*(1+'2.Assumptions'!$B$23)^(20-1) -> 5.2605182 | X10: ='2.Assumptions'!$B$22*(1+'2.Assumptions'!$B$23)^(21-1) -> 5.4183337 | Y10: ='2.Assumptions'!$B$22*(1+'2.Assumptions'!$B$23)^(22-1) -> 5.5808837 | Z10: ='2.Assumptions'!$B$22*(1+'2.Assumptions'!$B$23)^(23-1) -> 5.7483102 | AA10: ='2.Assumptions'!$B$22*(1+'2.Assumptions'!$B$23)^(24-1) -> 5.9207595 | AB10: ='2.Assumptions'!$B$22*(1+'2.Assumptions'!$B$23)^(25-1) -> 6.0983823
A11: Merchant revenue | B11: Cr | C11: 0 | D11: =D8*1000*D10/10000000 -> 45.023379 | E11: =E8*1000*E10/10000000 -> 45.947753 | F11: =F8*1000*F10/10000000 -> 46.889264 | G11: =G8*1000*G10/10000000 -> 47.848163 | H11: =H8*1000*H10/10000000 -> 48.824702 | I11: =I8*1000*I10/10000000 -> 49.819133 | J11: =J8*1000*J10/10000000 -> 50.831709 | K11: =K8*1000*K10/10000000 -> 51.862686 | ... AB11: =AB8*1000*AB10/10000000 -> 72.449453
A12: Peak (CfD) revenue | B12: Cr | C12: 0 | D12: =D9*1000*'4.Cashflow'!$B$2/10000000 -> 118.3695 | E12: =E9*1000*'4.Cashflow'!$B$2/10000000 -> 118.3695 | F12: =F9*1000*'4.Cashflow'!$B$2/10000000 -> 118.3695 | G12: =G9*1000*'4.Cashflow'!$B$2/10000000 -> 118.3695 | H12: =H9*1000*'4.Cashflow'!$B$2/10000000 -> 118.3695 | I12: =I9*1000*'4.Cashflow'!$B$2/10000000 -> 118.3695 | J12: =J9*1000*'4.Cashflow'!$B$2/10000000 -> 118.3695 | K12: =K9*1000*'4.Cashflow'!$B$2/10000000 -> 118.3695 | ... AB12: =AB9*1000*'4.Cashflow'!$B$2/10000000 -> 118.3695
A13: Total revenue | B13: Cr | C13: =0 -> 0 | D13: =D11+D12 -> 163.39288 | E13: =E11+E12 -> 164.31725 | F13: =F11+F12 -> 165.25876 | G13: =G11+G12 -> 166.21766 | H13: =H11+H12 -> 167.1942 | I13: =I11+I12 -> 168.18863 | J13: =J11+J12 -> 169.20121 | K13: =K11+K12 -> 170.23219 | ... AB13: =AB11+AB12 -> 190.81895
A14: O&M | B14: Cr | C14: 0 | D14: =('3.Sizing'!$B$11*'2.Assumptions'!$B$25+'3.Sizing'!$B$12*'2.Assumptions'!$B$26)*(1+'2.Assumptions'!$B$27)^(1-1) -> 14.75 | E14: =('3.Sizing'!$B$11*'2.Assumptions'!$B$25+'3.Sizing'!$B$12*'2.Assumptions'!$B$26)*(1+'2.Assumptions'!$B$27)^(2-1) -> 15.4875 | F14: =('3.Sizing'!$B$11*'2.Assumptions'!$B$25+'3.Sizing'!$B$12*'2.Assumptions'!$B$26)*(1+'2.Assumptions'!$B$27)^(3-1) -> 16.261875 | G14: =('3.Sizing'!$B$11*'2.Assumptions'!$B$25+'3.Sizing'!$B$12*'2.Assumptions'!$B$26)*(1+'2.Assumptions'!$B$27)^(4-1) -> 17.074969 | H14: =('3.Sizing'!$B$11*'2.Assumptions'!$B$25+'3.Sizing'!$B$12*'2.Assumptions'!$B$26)*(1+'2.Assumptions'!$B$27)^(5-1) -> 17.928717 | I14: =('3.Sizing'!$B$11*'2.Assumptions'!$B$25+'3.Sizing'!$B$12*'2.Assumptions'!$B$26)*(1+'2.Assumptions'!$B$27)^(6-1) -> 18.825153 | J14: =('3.Sizing'!$B$11*'2.Assumptions'!$B$25+'3.Sizing'!$B$12*'2.Assumptions'!$B$26)*(1+'2.Assumptions'!$B$27)^(7-1) -> 19.766411 | K14: =('3.Sizing'!$B$11*'2.Assumptions'!$B$25+'3.Sizing'!$B$12*'2.Assumptions'!$B$26)*(1+'2.Assumptions'!$B$27)^(8-1) -> 20.754731 | L14: =('3.Sizing'!$B$11*'2.Assumptions'!$B$25+'3.Sizing'!$B$12*'2.Assumptions'!$B$26)*(1+'2.Assumptions'!$B$27)^(9-1) -> 21.792468 | M14: =('3.Sizing'!$B$11*'2.Assumptions'!$B$25+'3.Sizing'!$B$12*'2.Assumptions'!$B$26)*(1+'2.Assumptions'!$B$27)^(10-1) -> 22.882091 | N14: =('3.Sizing'!$B$11*'2.Assumptions'!$B$25+'3.Sizing'!$B$12*'2.Assumptions'!$B$26)*(1+'2.Assumptions'!$B$27)^(11-1) -> 24.026196 | O14: =('3.Sizing'!$B$11*'2.Assumptions'!$B$25+'3.Sizing'!$B$12*'2.Assumptions'!$B$26)*(1+'2.Assumptions'!$B$27)^(12-1) -> 25.227506 | P14: =('3.Sizing'!$B$11*'2.Assumptions'!$B$25+'3.Sizing'!$B$12*'2.Assumptions'!$B$26)*(1+'2.Assumptions'!$B$27)^(13-1) -> 26.488881 | Q14: =('3.Sizing'!$B$11*'2.Assumptions'!$B$25+'3.Sizing'!$B$12*'2.Assumptions'!$B$26)*(1+'2.Assumptions'!$B$27)^(14-1) -> 27.813325 | R14: =('3.Sizing'!$B$11*'2.Assumptions'!$B$25+'3.Sizing'!$B$12*'2.Assumptions'!$B$26)*(1+'2.Assumptions'!$B$27)^(15-1) -> 29.203991 | S14: =('3.Sizing'!$B$11*'2.Assumptions'!$B$25+'3.Sizing'!$B$12*'2.Assumptions'!$B$26)*(1+'2.Assumptions'!$B$27)^(16-1) -> 30.664191 | T14: =('3.Sizing'!$B$11*'2.Assumptions'!$B$25+'3.Sizing'!$B$12*'2.Assumptions'!$B$26)*(1+'2.Assumptions'!$B$27)^(17-1) -> 32.1974 | U14: =('3.Sizing'!$B$11*'2.Assumptions'!$B$25+'3.Sizing'!$B$12*'2.Assumptions'!$B$26)*(1+'2.Assumptions'!$B$27)^(18-1) -> 33.80727 | V14: =('3.Sizing'!$B$11*'2.Assumptions'!$B$25+'3.Sizing'!$B$12*'2.Assumptions'!$B$26)*(1+'2.Assumptions'!$B$27)^(19-1) -> 35.497634 | W14: =('3.Sizing'!$B$11*'2.Assumptions'!$B$25+'3.Sizing'!$B$12*'2.Assumptions'!$B$26)*(1+'2.Assumptions'!$B$27)^(20-1) -> 37.272515 | X14: =('3.Sizing'!$B$11*'2.Assumptions'!$B$25+'3.Sizing'!$B$12*'2.Assumptions'!$B$26)*(1+'2.Assumptions'!$B$27)^(21-1) -> 39.136141 | Y14: =('3.Sizing'!$B$11*'2.Assumptions'!$B$25+'3.Sizing'!$B$12*'2.Assumptions'!$B$26)*(1+'2.Assumptions'!$B$27)^(22-1) -> 41.092948 | Z14: =('3.Sizing'!$B$11*'2.Assumptions'!$B$25+'3.Sizing'!$B$12*'2.Assumptions'!$B$26)*(1+'2.Assumptions'!$B$27)^(23-1) -> 43.147596 | AA14: =('3.Sizing'!$B$11*'2.Assumptions'!$B$25+'3.Sizing'!$B$12*'2.Assumptions'!$B$26)*(1+'2.Assumptions'!$B$27)^(24-1) -> 45.304975 | AB14: =('3.Sizing'!$B$11*'2.Assumptions'!$B$25+'3.Sizing'!$B$12*'2.Assumptions'!$B$26)*(1+'2.Assumptions'!$B$27)^(25-1) -> 47.570224
A15: EBITDA | B15: Cr | C15: 0 | D15: =D13-D14 -> 148.64288 | E15: =E13-E14 -> 148.82975 | F15: =F13-F14 -> 148.99689 | G15: =G13-G14 -> 149.14269 | H15: =H13-H14 -> 149.26548 | I15: =I13-I14 -> 149.36348 | J15: =J13-J14 -> 149.4348 | K15: =K13-K14 -> 149.47745 | ... AB15: =AB13-AB14 -> 143.24873
A16: Depreciation | B16: Cr | C16: 0 | D16: ='3.Sizing'!$B$13/'2.Assumptions'!$B$28 -> 38 | E16: ='3.Sizing'!$B$13/'2.Assumptions'!$B$28 -> 38 | F16: ='3.Sizing'!$B$13/'2.Assumptions'!$B$28 -> 38 | G16: ='3.Sizing'!$B$13/'2.Assumptions'!$B$28 -> 38 | H16: ='3.Sizing'!$B$13/'2.Assumptions'!$B$28 -> 38 | I16: ='3.Sizing'!$B$13/'2.Assumptions'!$B$28 -> 38 | J16: ='3.Sizing'!$B$13/'2.Assumptions'!$B$28 -> 38 | K16: ='3.Sizing'!$B$13/'2.Assumptions'!$B$28 -> 38 | ... AB16: ='3.Sizing'!$B$13/'2.Assumptions'!$B$28 -> 38
A17: Taxable income | B17: Cr | C17: 0 | D17: =MAX(D15-D16,0) -> 110.64288 | E17: =MAX(E15-E16,0) -> 110.82975 | F17: =MAX(F15-F16,0) -> 110.99689 | G17: =MAX(G15-G16,0) -> 111.14269 | H17: =MAX(H15-H16,0) -> 111.26548 | I17: =MAX(I15-I16,0) -> 111.36348 | J17: =MAX(J15-J16,0) -> 111.4348 | K17: =MAX(K15-K16,0) -> 111.47745 | ... AB17: =MAX(AB15-AB16,0) -> 105.24873
A18: Tax | B18: Cr | C18: 0 | D18: =D17*'2.Assumptions'!$B$30 -> 27.66072 | E18: =E17*'2.Assumptions'!$B$30 -> 27.707438 | F18: =F17*'2.Assumptions'!$B$30 -> 27.749222 | G18: =G17*'2.Assumptions'!$B$30 -> 27.785674 | H18: =H17*'2.Assumptions'!$B$30 -> 27.816371 | I18: =I17*'2.Assumptions'!$B$30 -> 27.84087 | J18: =J17*'2.Assumptions'!$B$30 -> 27.8587 | K18: =K17*'2.Assumptions'!$B$30 -> 27.869364 | ... AB18: =AB17*'2.Assumptions'!$B$30 -> 26.312182
A19: Capex | B19: Cr | C19: =-'3.Sizing'!$B$13 -> -950 | D19: 0 | E19: 0 | F19: 0 | G19: 0 | H19: 0 | I19: 0 | J19: 0 | K19: 0 | L19: 0 | M19: 0 | N19: 0 | O19: 0 | P19: 0 | Q19: 0 | R19: 0 | S19: 0 | T19: 0 | U19: 0 | V19: 0 | W19: 0 | X19: 0 | Y19: 0 | Z19: 0 | AA19: 0 | AB19: 0
A20: Unlevered FCF | B20: Cr | C20: =C15-C18+C19 -> -950 | D20: =D15-D18 -> 120.98216 | E20: =E15-E18 -> 121.12232 | F20: =F15-F18 -> 121.24767 | G20: =G15-G18 -> 121.35702 | H20: =H15-H18 -> 121.44911 | I20: =I15-I18 -> 121.52261 | J20: =J15-J18 -> 121.5761 | K20: =K15-K18 -> 121.60809 | ... AB20: =AB15-AB18 -> 116.93655

Sheet 5.Financing_EIRR
A1: FINANCING & EQUITY IRR (base case, market multiplier = 1.0)
A2: Equity IRR | B2: =IRR(C12:AB12) -> 0.17356684 | D2: Debt = 70% x capex; 15-yr equal-principal @ 9%. Tax shield on interest included.
A4: Rs Cr | B4: Unit | C4: 0 | D4: 1 | E4: 2 | F4: 3 | G4: 4 | H4: 5 | I4: 6 | J4: 7 | K4: 8 | L4: 9 | M4: 10 | N4: 11 | O4: 12 | P4: 13 | Q4: 14 | R4: 15 | S4: 16 | T4: 17 | U4: 18 | V4: 19 | W4: 20 | X4: 21 | Y4: 22 | Z4: 23 | AA4: 24 | AB4: 25
A5: EBITDA (from Cashflow) | B5: Cr | C5: ='4.Cashflow'!C15 -> 0 | D5: ='4.Cashflow'!D15 -> 148.64288 | E5: ='4.Cashflow'!E15 -> 148.82975 | F5: ='4.Cashflow'!F15 -> 148.99689 | G5: ='4.Cashflow'!G15 -> 149.14269 | H5: ='4.Cashflow'!H15 -> 149.26548 | I5: ='4.Cashflow'!I15 -> 149.36348 | J5: ='4.Cashflow'!J15 -> 149.4348 | ... AB5: ='4.Cashflow'!AB15 -> 143.24873
A6: Debt balance (open) | B6: Cr | C6: ='3.Sizing'!$B$13*'2.Assumptions'!$B$33 -> 665 | D6: =MAX(C6-C8,0) -> 665 | E6: =MAX(D6-D8,0) -> 620.66667 | F6: =MAX(E6-E8,0) -> 576.33333 | G6: =MAX(F6-F8,0) -> 532 | H6: =MAX(G6-G8,0) -> 487.66667 | I6: =MAX(H6-H8,0) -> 443.33333 | J6: =MAX(I6-I8,0) -> 399 | K6: =MAX(J6-J8,0) -> 354.66667 | ... AB6: =MAX(AA6-AA8,0) -> 0
A7: Interest | B7: Cr | C7: 0 | D7: =IF(1<='2.Assumptions'!$B$35,D6*'2.Assumptions'!$B$34,0) -> 59.85 | E7: =IF(2<='2.Assumptions'!$B$35,E6*'2.Assumptions'!$B$34,0) -> 55.86 | F7: =IF(3<='2.Assumptions'!$B$35,F6*'2.Assumptions'!$B$34,0) -> 51.87 | G7: =IF(4<='2.Assumptions'!$B$35,G6*'2.Assumptions'!$B$34,0) -> 47.88 | H7: =IF(5<='2.Assumptions'!$B$35,H6*'2.Assumptions'!$B$34,0) -> 43.89 | I7: =IF(6<='2.Assumptions'!$B$35,I6*'2.Assumptions'!$B$34,0) -> 39.9 | J7: =IF(7<='2.Assumptions'!$B$35,J6*'2.Assumptions'!$B$34,0) -> 35.91 | K7: =IF(8<='2.Assumptions'!$B$35,K6*'2.Assumptions'!$B$34,0) -> 31.92 | L7: =IF(9<='2.Assumptions'!$B$35,L6*'2.Assumptions'!$B$34,0) -> 27.93 | M7: =IF(10<='2.Assumptions'!$B$35,M6*'2.Assumptions'!$B$34,0) -> 23.94 | N7: =IF(11<='2.Assumptions'!$B$35,N6*'2.Assumptions'!$B$34,0) -> 19.95 | O7: =IF(12<='2.Assumptions'!$B$35,O6*'2.Assumptions'!$B$34,0) -> 15.96 | P7: =IF(13<='2.Assumptions'!$B$35,P6*'2.Assumptions'!$B$34,0) -> 11.97 | Q7: =IF(14<='2.Assumptions'!$B$35,Q6*'2.Assumptions'!$B$34,0) -> 7.98 | R7: =IF(15<='2.Assumptions'!$B$35,R6*'2.Assumptions'!$B$34,0) -> 3.99 | S7: =IF(16<='2.Assumptions'!$B$35,S6*'2.Assumptions'!$B$34,0) -> 0 | T7: =IF(17<='2.Assumptions'!$B$35,T6*'2.Assumptions'!$B$34,0) -> 0 | U7: =IF(18<='2.Assumptions'!$B$35,U6*'2.Assumptions'!$B$34,0) -> 0 | V7: =IF(19<='2.Assumptions'!$B$35,V6*'2.Assumptions'!$B$34,0) -> 0 | W7: =IF(20<='2.Assumptions'!$B$35,W6*'2.Assumptions'!$B$34,0) -> 0 | X7: =IF(21<='2.Assumptions'!$B$35,X6*'2.Assumptions'!$B$34,0) -> 0 | Y7: =IF(22<='2.Assumptions'!$B$35,Y6*'2.Assumptions'!$B$34,0) -> 0 | Z7: =IF(23<='2.Assumptions'!$B$35,Z6*'2.Assumptions'!$B$34,0) -> 0 | AA7: =IF(24<='2.Assumptions'!$B$35,AA6*'2.Assumptions'!$B$34,0) -> 0 | AB7: =IF(25<='2.Assumptions'!$B$35,AB6*'2.Assumptions'!$B$34,0) -> 0
A8: Principal repay | B8: Cr | C8: 0 | D8: =IF(1<='2.Assumptions'!$B$35,('3.Sizing'!$B$13*'2.Assumptions'!$B$33)/'2.Assumptions'!$B$35,0) -> 44.333333 | E8: =IF(2<='2.Assumptions'!$B$35,('3.Sizing'!$B$13*'2.Assumptions'!$B$33)/'2.Assumptions'!$B$35,0) -> 44.333333 | F8: =IF(3<='2.Assumptions'!$B$35,('3.Sizing'!$B$13*'2.Assumptions'!$B$33)/'2.Assumptions'!$B$35,0) -> 44.333333 | G8: =IF(4<='2.Assumptions'!$B$35,('3.Sizing'!$B$13*'2.Assumptions'!$B$33)/'2.Assumptions'!$B$35,0) -> 44.333333 | H8: =IF(5<='2.Assumptions'!$B$35,('3.Sizing'!$B$13*'2.Assumptions'!$B$33)/'2.Assumptions'!$B$35,0) -> 44.333333 | I8: =IF(6<='2.Assumptions'!$B$35,('3.Sizing'!$B$13*'2.Assumptions'!$B$33)/'2.Assumptions'!$B$35,0) -> 44.333333 | J8: =IF(7<='2.Assumptions'!$B$35,('3.Sizing'!$B$13*'2.Assumptions'!$B$33)/'2.Assumptions'!$B$35,0) -> 44.333333 | K8: =IF(8<='2.Assumptions'!$B$35,('3.Sizing'!$B$13*'2.Assumptions'!$B$33)/'2.Assumptions'!$B$35,0) -> 44.333333 | L8: =IF(9<='2.Assumptions'!$B$35,('3.Sizing'!$B$13*'2.Assumptions'!$B$33)/'2.Assumptions'!$B$35,0) -> 44.333333 | M8: =IF(10<='2.Assumptions'!$B$35,('3.Sizing'!$B$13*'2.Assumptions'!$B$33)/'2.Assumptions'!$B$35,0) -> 44.333333 | N8: =IF(11<='2.Assumptions'!$B$35,('3.Sizing'!$B$13*'2.Assumptions'!$B$33)/'2.Assumptions'!$B$35,0) -> 44.333333 | O8: =IF(12<='2.Assumptions'!$B$35,('3.Sizing'!$B$13*'2.Assumptions'!$B$33)/'2.Assumptions'!$B$35,0) -> 44.333333 | P8: =IF(13<='2.Assumptions'!$B$35,('3.Sizing'!$B$13*'2.Assumptions'!$B$33)/'2.Assumptions'!$B$35,0) -> 44.333333 | Q8: =IF(14<='2.Assumptions'!$B$35,('3.Sizing'!$B$13*'2.Assumptions'!$B$33)/'2.Assumptions'!$B$35,0) -> 44.333333 | R8: =IF(15<='2.Assumptions'!$B$35,('3.Sizing'!$B$13*'2.Assumptions'!$B$33)/'2.Assumptions'!$B$35,0) -> 44.333333 | S8: =IF(16<='2.Assumptions'!$B$35,('3.Sizing'!$B$13*'2.Assumptions'!$B$33)/'2.Assumptions'!$B$35,0) -> 0 | T8: =IF(17<='2.Assumptions'!$B$35,('3.Sizing'!$B$13*'2.Assumptions'!$B$33)/'2.Assumptions'!$B$35,0) -> 0 | U8: =IF(18<='2.Assumptions'!$B$35,('3.Sizing'!$B$13*'2.Assumptions'!$B$33)/'2.Assumptions'!$B$35,0) -> 0 | V8: =IF(19<='2.Assumptions'!$B$35,('3.Sizing'!$B$13*'2.Assumptions'!$B$33)/'2.Assumptions'!$B$35,0) -> 0 | W8: =IF(20<='2.Assumptions'!$B$35,('3.Sizing'!$B$13*'2.Assumptions'!$B$33)/'2.Assumptions'!$B$35,0) -> 0 | X8: =IF(21<='2.Assumptions'!$B$35,('3.Sizing'!$B$13*'2.Assumptions'!$B$33)/'2.Assumptions'!$B$35,0) -> 0 | Y8: =IF(22<='2.Assumptions'!$B$35,('3.Sizing'!$B$13*'2.Assumptions'!$B$33)/'2.Assumptions'!$B$35,0) -> 0 | Z8: =IF(23<='2.Assumptions'!$B$35,('3.Sizing'!$B$13*'2.Assumptions'!$B$33)/'2.Assumptions'!$B$35,0) -> 0 | AA8: =IF(24<='2.Assumptions'!$B$35,('3.Sizing'!$B$13*'2.Assumptions'!$B$33)/'2.Assumptions'!$B$35,0) -> 0 | AB8: =IF(25<='2.Assumptions'!$B$35,('3.Sizing'!$B$13*'2.Assumptions'!$B$33)/'2.Assumptions'!$B$35,0) -> 0
A9: Depreciation | B9: Cr | C9: 0 | D9: ='3.Sizing'!$B$13/'2.Assumptions'!$B$28 -> 38 | E9: ='3.Sizing'!$B$13/'2.Assumptions'!$B$28 -> 38 | F9: ='3.Sizing'!$B$13/'2.Assumptions'!$B$28 -> 38 | G9: ='3.Sizing'!$B$13/'2.Assumptions'!$B$28 -> 38 | H9: ='3.Sizing'!$B$13/'2.Assumptions'!$B$28 -> 38 | I9: ='3.Sizing'!$B$13/'2.Assumptions'!$B$28 -> 38 | J9: ='3.Sizing'!$B$13/'2.Assumptions'!$B$28 -> 38 | K9: ='3.Sizing'!$B$13/'2.Assumptions'!$B$28 -> 38 | ... AB9: ='3.Sizing'!$B$13/'2.Assumptions'!$B$28 -> 38
A10: Taxable income | B10: Cr | C10: 0 | D10: =MAX(D5-D9-D7,0) -> 50.792879 | E10: =MAX(E5-E9-E7,0) -> 54.969753 | F10: =MAX(F5-F9-F7,0) -> 59.126889 | G10: =MAX(G5-G9-G7,0) -> 63.262695 | H10: =MAX(H5-H9-H7,0) -> 67.375485 | I10: =MAX(I5-I9-I7,0) -> 71.46348 | J10: =MAX(J5-J9-J7,0) -> 75.524799 | K10: =MAX(K5-K9-K7,0) -> 79.557454 | ... AB10: =MAX(AB5-AB9-AB7,0) -> 105.24873
A11: Tax | B11: Cr | C11: 0 | D11: =D10*'2.Assumptions'!$B$30 -> 12.69822 | E11: =E10*'2.Assumptions'!$B$30 -> 13.742438 | F11: =F10*'2.Assumptions'!$B$30 -> 14.781722 | G11: =G10*'2.Assumptions'!$B$30 -> 15.815674 | H11: =H10*'2.Assumptions'!$B$30 -> 16.843871 | I11: =I10*'2.Assumptions'!$B$30 -> 17.86587 | J11: =J10*'2.Assumptions'!$B$30 -> 18.8812 | K11: =K10*'2.Assumptions'!$B$30 -> 19.889364 | ... AB11: =AB10*'2.Assumptions'!$B$30 -> 26.312182
A12: Equity cash flow | B12: Cr | C12: =-'3.Sizing'!$B$13*(1-'2.Assumptions'!$B$33) -> -285 | D12: =D5-D11-D7-D8 -> 31.761326 | E12: =E5-E11-E7-E8 -> 34.893982 | F12: =F5-F11-F7-F8 -> 38.011834 | G12: =G5-G11-G7-G8 -> 41.113688 | H12: =H5-H11-H7-H8 -> 44.19828 | I12: =I5-I11-I7-I8 -> 47.264276 | J12: =J5-J11-J7-J8 -> 50.310266 | K12: =K5-K11-K7-K8 -> 53.334758 | ... AB12: =AB5-AB11-AB7-AB8 -> 116.93655

Sheet 6.Sensitivity
A1: SENSITIVITY: MARKET PRICE +/-10% (same strike) -> Equity IRR & Pool economics
A2: Strike held constant. A price move flexes (i) merchant day-sales and (ii) gain-share above strike; pool top-up = what SECI pays the developer.
A4: SUMMARY
C5: Market -10% | D5: Base | E5: Market +10%
A6: Market price multiplier | C6: 0.9 | D6: 1 | E6: 1.1
A7: Equity IRR | C7: =IRR(C14:C39) -> 0.16323567 | D7: =IRR(D14:D39) -> 0.17356684 | E7: =IRR(E14:E39) -> 0.18392951
A8: Change vs base (ppt) | C8: =(C7-$D$7)*100 -> -1.033117 | D8: =(D7-$D$7)*100 -> 0 | E8: =(E7-$D$7)*100 -> 1.0362668
A9: Realized peak price yr1 (Rs/kWh) | C9: ='4.Cashflow'!$B$2+'2.Assumptions'!$B$36*MAX('2.Assumptions'!$B$21*$C$6-'4.Cashflow'!$B$2,0) -> 10.81 | D9: ='4.Cashflow'!$B$2+'2.Assumptions'!$B$36*MAX('2.Assumptions'!$B$21*$D$6-'4.Cashflow'!$B$2,0) -> 10.81 | E9: ='4.Cashflow'!$B$2+'2.Assumptions'!$B$36*MAX('2.Assumptions'!$B$21*$E$6-'4.Cashflow'!$B$2,0) -> 10.81
A10: SECI pool top-up yr1 (Rs Cr, + = SECI pays) | C10: =IF('2.Assumptions'!$B$21*$C$6<'4.Cashflow'!$B$2,('4.Cashflow'!$B$2-'2.Assumptions'!$B$21*$C$6),-(1-'2.Assumptions'!$B$36)*('2.Assumptions'!$B$21*$C$6-'4.Cashflow'!$B$2))*'3.Sizing'!$B$7*1000/10000000 -> 59.2395 | D10: =IF('2.Assumptions'!$B$21*$D$6<'4.Cashflow'!$B$2,('4.Cashflow'!$B$2-'2.Assumptions'!$B$21*$D$6),-(1-'2.Assumptions'!$B$36)*('2.Assumptions'!$B$21*$D$6-'4.Cashflow'!$B$2))*'3.Sizing'!$B$7*1000/10000000 -> 52.6695 | E10: =IF('2.Assumptions'!$B$21*$E$6<'4.Cashflow'!$B$2,('4.Cashflow'!$B$2-'2.Assumptions'!$B$21*$E$6),-(1-'2.Assumptions'!$B$36)*('2.Assumptions'!$B$21*$E$6-'4.Cashflow'!$B$2))*'3.Sizing'!$B$7*1000/10000000 -> 46.0995
A12: EQUITY CASH FLOW ENGINE (Rs Cr) - drives the IRRs above
A13: Year | C13: Market -10% | D13: Base | E13: Market +10%
A14: 0 | C14: =-'3.Sizing'!$B$13*(1-'2.Assumptions'!$B$33) -> -285 | D14: =-'3.Sizing'!$B$13*(1-'2.Assumptions'!$B$33) -> -285 | E14: =-'3.Sizing'!$B$13*(1-'2.Assumptions'!$B$33) -> -285
A15: 1 | C15: =(MAX('3.Sizing'!$B$4*(1-'2.Assumptions'!$B$12)^(1-1)-'3.Sizing'!$B$5,0)*1000*('2.Assumptions'!$B$22*$C$6*(1+'2.Assumptions'!$B$23)^(1-1))/10000000+'3.Sizing'!$B$7*1000*('4.Cashflow'!$B$2+'2.Assumptions'!$B$36*MAX('2.Assumptions'!$B$21*$C$6-'4.Cashflow'!$B$2,0))/10000000-('3.Sizing'!$B$11*'2.Assumptions'!$B$25+'3.Sizing'!$B$12*'2.Assumptions'!$B$26)*(1+'2.Assumptions'!$B$27)^(1-1))-(MAX((MAX('3.Sizing'!$B$4*(1-'2.Assumptions'!$B$12)^(1-1)-'3.Sizing'!$B$5,0)*1000*('2.Assumptions'!$B$22*$C$6*(1+'2.Assumptions'!$B$23)^(1-1))/10000000+'3.Sizing'!$B$7*1000*('4.Cashflow'!$B$2+'2.Assumptions'!$B$36*MAX('2.Assumptions'!$B$21*$C$6-'4.Cashflow'!$B$2,0))/10000000-('3.Sizing'!$B$11*'2.Assumptions'!$B$25+'3.Sizing'!$B$12*'2.Assumptions'!$B$26)*(1+'2.Assumptions'!$B$27)^(1-1))-'3.Sizing'!$B$13/'2.Assumptions'!$B$28-IF(1<='2.Assumptions'!$B$35,('3.Sizing'!$B$13*'2.Assumptions'!$B$33-('3.Sizing'!$B$13*'2.Assumptions'!$B$33/'2.Assumptions'!$B$35)*(1-1))*'2.Assumptions'!$B$34,0),0)*'2.Assumptions'!$B$30)-(IF(1<='2.Assumptions'!$B$35,('3.Sizing'!$B$13*'2.Assumptions'!$B$33-('3.Sizing'!$B$13*'2.Assumptions'!$B$33/'2.Assumptions'!$B$35)*(1-1))*'2.Assumptions'!$B$34,0))-(IF(1<='2.Assumptions'!$B$35,('3.Sizing'!$B$13*'2.Assumptions'!$B$33)/'2.Assumptions'!$B$35,0)) -> 28.384573 | D15: =(MAX('3.Sizing'!$B$4*(1-'2.Assumptions'!$B$12)^(1-1)-'3.Sizing'!$B$5,0)*1000*('2.Assumptions'!$B$22*$D$6*(1+'2.Assumptions'!$B$23)^(1-1))/10000000+'3.Sizing'!$B$7*1000*('4.Cashflow'!$B$2+'2.Assumptions'!$B$36*MAX('2.Assumptions'!$B$21*$D$6-'4.Cashflow'!$B$2,0))/10000000-('3.Sizing'!$B$11*'2.Assumptions'!$B$25+'3.Sizing'!$B$12*'2.Assumptions'!$B$26)*(1+'2.Assumptions'!$B$27)^(1-1))-(MAX((MAX('3.Sizing'!$B$4*(1-'2.Assumptions'!$B$12)^(1-1)-'3.Sizing'!$B$5,0)*1000*('2.Assumptions'!$B$22*$D$6*(1+'2.Assumptions'!$B$23)^(1-1))/10000000+'3.Sizing'!$B$7*1000*('4.Cashflow'!$B$2+'2.Assumptions'!$B$36*MAX('2.Assumptions'!$B$21*$D$6-'4.Cashflow'!$B$2,0))/10000000-('3.Sizing'!$B$11*'2.Assumptions'!$B$25+'3.Sizing'!$B$12*'2.Assumptions'!$B$26)*(1+'2.Assumptions'!$B$27)^(1-1))-'3.Sizing'!$B$13/'2.Assumptions'!$B$28-IF(1<='2.Assumptions'!$B$35,('3.Sizing'!$B$13*'2.Assumptions'!$B$33-('3.Sizing'!$B$13*'2.Assumptions'!$B$33/'2.Assumptions'!$B$35)*(1-1))*'2.Assumptions'!$B$34,0),0)*'2.Assumptions'!$B$30)-(IF(1<='2.Assumptions'!$B$35,('3.Sizing'!$B$13*'2.Assumptions'!$B$33-('3.Sizing'!$B$13*'2.Assumptions'!$B$33/'2.Assumptions'!$B$35)*(1-1))*'2.Assumptions'!$B$34,0))-(IF(1<='2.Assumptions'!$B$35,('3.Sizing'!$B$13*'2.Assumptions'!$B$33)/'2.Assumptions'!$B$35,0)) -> 31.761326 | E15: =(MAX('3.Sizing'!$B$4*(1-'2.Assumptions'!$B$12)^(1-1)-'3.Sizing'!$B$5,0)*1000*('2.Assumptions'!$B$22*$E$6*(1+'2.Assumptions'!$B$23)^(1-1))/10000000+'3.Sizing'!$B$7*1000*('4.Cashflow'!$B$2+'2.Assumptions'!$B$36*MAX('2.Assumptions'!$B$21*$E$6-'4.Cashflow'!$B$2,0))/10000000-('3.Sizing'!$B$11*'2.Assumptions'!$B$25+'3.Sizing'!$B$12*'2.Assumptions'!$B$26)*(1+'2.Assumptions'!$B$27)^(1-1))-(MAX((MAX('3.Sizing'!$B$4*(1-'2.Assumptions'!$B$12)^(1-1)-'3.Sizing'!$B$5,0)*1000*('2.Assumptions'!$B$22*$E$6*(1+'2.Assumptions'!$B$23)^(1-1))/10000000+'3.Sizing'!$B$7*1000*('4.Cashflow'!$B$2+'2.Assumptions'!$B$36*MAX('2.Assumptions'!$B$21*$E$6-'4.Cashflow'!$B$2,0))/10000000-('3.Sizing'!$B$11*'2.Assumptions'!$B$25+'3.Sizing'!$B$12*'2.Assumptions'!$B$26)*(1+'2.Assumptions'!$B$27)^(1-1))-'3.Sizing'!$B$13/'2.Assumptions'!$B$28-IF(1<='2.Assumptions'!$B$35,('3.Sizing'!$B$13*'2.Assumptions'!$B$33-('3.Sizing'!$B$13*'2.Assumptions'!$B$33/'2.Assumptions'!$B$35)*(1-1))*'2.Assumptions'!$B$34,0),0)*'2.Assumptions'!$B$30)-(IF(1<='2.Assumptions'!$B$35,('3.Sizing'!$B$13*'2.Assumptions'!$B$33-('3.Sizing'!$B$13*'2.Assumptions'!$B$33/'2.Assumptions'!$B$35)*(1-1))*'2.Assumptions'!$B$34,0))-(IF(1<='2.Assumptions'!$B$35,('3.Sizing'!$B$13*'2.Assumptions'!$B$33)/'2.Assumptions'!$B$35,0)) -> 35.13808
A16: 2 | C16: =(MAX('3.Sizing'!$B$4*(1-'2.Assumptions'!$B$12)^(2-1)-'3.Sizing'!$B$5,0)*1000*('2.Assumptions'!$B$22*$C$6*(1+'2.Assumptions'!$B$23)^(2-1))/10000000+'3.Sizing'!$B$7*1000*('4.Cashflow'!$B$2+'2.Assumptions'!$B$36*MAX('2.Assumptions'!$B$21*$C$6-'4.Cashflow'!$B$2,0))/10000000-('3.Sizing'!$B$11*'2.Assumptions'!$B$25+'3.Sizing'!$B$12*'2.Assumptions'!$B$26)*(1+'2.Assumptions'!$B$27)^(2-1))-(MAX((MAX('3.Sizing'!$B$4*(1-'2.Assumptions'!$B$12)^(2-1)-'3.Sizing'!$B$5,0)*1000*('2.Assumptions'!$B$22*$C$6*(1+'2.Assumptions'!$B$23)^(2-1))/10000000+'3.Sizing'!$B$7*1000*('4.Cashflow'!$B$2+'2.Assumptions'!$B$36*MAX('2.Assumptions'!$B$21*$C$6-'4.Cashflow'!$B$2,0))/10000000-('3.Sizing'!$B$11*'2.Assumptions'!$B$25+'3.Sizing'!$B$12*'2.Assumptions'!$B$26)*(1+'2.Assumptions'!$B$27)^(2-1))-'3.Sizing'!$B$13/'2.Assumptions'!$B$28-IF(2<='2.Assumptions'!$B$35,('3.Sizing'!$B$13*'2.Assumptions'!$B$33-('3.Sizing'!$B$13*'2.Assumptions'!$B$33/'2.Assumptions'!$B$35)*(2-1))*'2.Assumptions'!$B$34,0),0)*'2.Assumptions'!$B$30)-(IF(2<='2.Assumptions'!$B$35,('3.Sizing'!$B$13*'2.Assumptions'!$B$33-('3.Sizing'!$B$13*'2.Assumptions'!$B$33/'2.Assumptions'!$B$35)*(2-1))*'2.Assumptions'!$B$34,0))-(IF(2<='2.Assumptions'!$B$35,('3.Sizing'!$B$13*'2.Assumptions'!$B$33)/'2.Assumptions'!$B$35,0)) -> 31.4479 | D16: =(MAX('3.Sizing'!$B$4*(1-'2.Assumptions'!$B$12)^(2-1)-'3.Sizing'!$B$5,0)*1000*('2.Assumptions'!$B$22*$D$6*(1+'2.Assumptions'!$B$23)^(2-1))/10000000+'3.Sizing'!$B$7*1000*('4.Cashflow'!$B$2+'2.Assumptions'!$B$36*MAX('2.Assumptions'!$B$21*$D$6-'4.Cashflow'!$B$2,0))/10000000-('3.Sizing'!$B$11*'2.Assumptions'!$B$25+'3.Sizing'!$B$12*'2.Assumptions'!$B$26)*(1+'2.Assumptions'!$B$27)^(2-1))-(MAX((MAX('3.Sizing'!$B$4*(1-'2.Assumptions'!$B$12)^(2-1)-'3.Sizing'!$B$5,0)*1000*('2.Assumptions'!$B$22*$D$6*(1+'2.Assumptions'!$B$23)^(2-1))/10000000+'3.Sizing'!$B$7*1000*('4.Cashflow'!$B$2+'2.Assumptions'!$B$36*MAX('2.Assumptions'!$B$21*$D$6-'4.Cashflow'!$B$2,0))/10000000-('3.Sizing'!$B$11*'2.Assumptions'!$B$25+'3.Sizing'!$B$12*'2.Assumptions'!$B$26)*(1+'2.Assumptions'!$B$27)^(2-1))-'3.Sizing'!$B$13/'2.Assumptions'!$B$28-IF(2<='2.Assumptions'!$B$35,('3.Sizing'!$B$13*'2.Assumptions'!$B$33-('3.Sizing'!$B$13*'2.Assumptions'!$B$33/'2.Assumptions'!$B$35)*(2-1))*'2.Assumptions'!$B$34,0),0)*'2.Assumptions'!$B$30)-(IF(2<='2.Assumptions'!$B$35,('3.Sizing'!$B$13*'2.Assumptions'!$B$33-('3.Sizing'!$B$13*'2.Assumptions'!$B$33/'2.Assumptions'!$B$35)*(2-1))*'2.Assumptions'!$B$34,0))-(IF(2<='2.Assumptions'!$B$35,('3.Sizing'!$B$13*'2.Assumptions'!$B$33)/'2.Assumptions'!$B$35,0)) -> 34.893982 | E16: =(MAX('3.Sizing'!$B$4*(1-'2.Assumptions'!$B$12)^(2-1)-'3.Sizing'!$B$5,0)*1000*('2.Assumptions'!$B$22*$E$6*(1+'2.Assumptions'!$B$23)^(2-1))/10000000+'3.Sizing'!$B$7*1000*('4.Cashflow'!$B$2+'2.Assumptions'!$B$36*MAX('2.Assumptions'!$B$21*$E$6-'4.Cashflow'!$B$2,0))/10000000-('3.Sizing'!$B$11*'2.Assumptions'!$B$25+'3.Sizing'!$B$12*'2.Assumptions'!$B$26)*(1+'2.Assumptions'!$B$27)^(2-1))-(MAX((MAX('3.Sizing'!$B$4*(1-'2.Assumptions'!$B$12)^(2-1)-'3.Sizing'!$B$5,0)*1000*('2.Assumptions'!$B$22*$E$6*(1+'2.Assumptions'!$B$23)^(2-1))/10000000+'3.Sizing'!$B$7*1000*('4.Cashflow'!$B$2+'2.Assumptions'!$B$36*MAX('2.Assumptions'!$B$21*$E$6-'4.Cashflow'!$B$2,0))/10000000-('3.Sizing'!$B$11*'2.Assumptions'!$B$25+'3.Sizing'!$B$12*'2.Assumptions'!$B$26)*(1+'2.Assumptions'!$B$27)^(2-1))-'3.Sizing'!$B$13/'2.Assumptions'!$B$28-IF(2<='2.Assumptions'!$B$35,('3.Sizing'!$B$13*'2.Assumptions'!$B$33-('3.Sizing'!$B$13*'2.Assumptions'!$B$33/'2.Assumptions'!$B$35)*(2-1))*'2.Assumptions'!$B$34,0),0)*'2.Assumptions'!$B$30)-(IF(2<='2.Assumptions'!$B$35,('3.Sizing'!$B$13*'2.Assumptions'!$B$33-('3.Sizing'!$B$13*'2.Assumptions'!$B$33/'2.Assumptions'!$B$35)*(2-1))*'2.Assumptions'!$B$34,0))-(IF(2<='2.Assumptions'!$B$35,('3.Sizing'!$B$13*'2.Assumptions'!$B$33)/'2.Assumptions'!$B$35,0)) -> 38.340063
A17: 3 | C17: =(MAX('3.Sizing'!$B$4*(1-'2.Assumptions'!$B$12)^(3-1)-'3.Sizing'!$B$5,0)*1000*('2.Assumptions'!$B$22*$C$6*(1+'2.Assumptions'!$B$23)^(3-1))/10000000+'3.Sizing'!$B$7*1000*('4.Cashflow'!$B$2+'2.Assumptions'!$B$36*MAX('2.Assumptions'!$B$21*$C$6-'4.Cashflow'!$B$2,0))/10000000-('3.Sizing'!$B$11*'2.Assumptions'!$B$25+'3.Sizing'!$B$12*'2.Assumptions'!$B$26)*(1+'2.Assumptions'!$B$27)^(3-1))-(MAX((MAX('3.Sizing'!$B$4*(1-'2.Assumptions'!$B$12)^(3-1)-'3.Sizing'!$B$5,0)*1000*('2.Assumptions'!$B$22*$C$6*(1+'2.Assumptions'!$B$23)^(3-1))/10000000+'3.Sizing'!$B$7*1000*('4.Cashflow'!$B$2+'2.Assumptions'!$B$36*MAX('2.Assumptions'!$B$21*$C$6-'4.Cashflow'!$B$2,0))/10000000-('3.Sizing'!$B$11*'2.Assumptions'!$B$25+'3.Sizing'!$B$12*'2.Assumptions'!$B$26)*(1+'2.Assumptions'!$B$27)^(3-1))-'3.Sizing'!$B$13/'2.Assumptions'!$B$28-IF(3<='2.Assumptions'!$B$35,('3.Sizing'!$B$13*'2.Assumptions'!$B$33-('3.Sizing'!$B$13*'2.Assumptions'!$B$33/'2.Assumptions'!$B$35)*(3-1))*'2.Assumptions'!$B$34,0),0)*'2.Assumptions'!$B$30)-(IF(3<='2.Assumptions'!$B$35,('3.Sizing'!$B$13*'2.Assumptions'!$B$33-('3.Sizing'!$B$13*'2.Assumptions'!$B$33/'2.Assumptions'!$B$35)*(3-1))*'2.Assumptions'!$B$34,0))-(IF(3<='2.Assumptions'!$B$35,('3.Sizing'!$B$13*'2.Assumptions'!$B$33)/'2.Assumptions'!$B$35,0)) -> 34.495139 | D17: =(MAX('3.Sizing'!$B$4*(1-'2.Assumptions'!$B$12)^(3-1)-'3.Sizing'!$B$5,0)*1000*('2.Assumptions'!$B$22*$D$6*(1+'2.Assumptions'!$B$23)^(3-1))/10000000+'3.Sizing'!$B$7*1000*('4.Cashflow'!$B$2+'2.Assumptions'!$B$36*MAX('2.Assumptions'!$B$21*$D$6-'4.Cashflow'!$B$2,0))/10000000-('3.Sizing'!$B$11*'2.Assumptions'!$B$25+'3.Sizing'!$B$12*'2.Assumptions'!$B$26)*(1+'2.Assumptions'!$B$27)^(3-1))-(MAX((MAX('3.Sizing'!$B$4*(1-'2.Assumptions'!$B$12)^(3-1)-'3.Sizing'!$B$5,0)*1000*('2.Assumptions'!$B$22*$D$6*(1+'2.Assumptions'!$B$23)^(3-1))/10000000+'3.Sizing'!$B$7*1000*('4.Cashflow'!$B$2+'2.Assumptions'!$B$36*MAX('2.Assumptions'!$B$21*$D$6-'4.Cashflow'!$B$2,0))/10000000-('3.Sizing'!$B$11*'2.Assumptions'!$B$25+'3.Sizing'!$B$12*'2.Assumptions'!$B$26)*(1+'2.Assumptions'!$B$27)^(3-1))-'3.Sizing'!$B$13/'2.Assumptions'!$B$28-IF(3<='2.Assumptions'!$B$35,('3.Sizing'!$B$13*'2.Assumptions'!$B$33-('3.Sizing'!$B$13*'2.Assumptions'!$B$33/'2.Assumptions'!$B$35)*(3-1))*'2.Assumptions'!$B$34,0),0)*'2.Assumptions'!$B$30)-(IF(3<='2.Assumptions'!$B$35,('3.Sizing'!$B$13*'2.Assumptions'!$B$33-('3.Sizing'!$B$13*'2.Assumptions'!$B$33/'2.Assumptions'!$B$35)*(3-1))*'2.Assumptions'!$B$34,0))-(IF(3<='2.Assumptions'!$B$35,('3.Sizing'!$B$13*'2.Assumptions'!$B$33)/'2.Assumptions'!$B$35,0)) -> 38.011834 | E17: =(MAX('3.Sizing'!$B$4*(1-'2.Assumptions'!$B$12)^(3-1)-'3.Sizing'!$B$5,0)*1000*('2.Assumptions'!$B$22*$E$6*(1+'2.Assumptions'!$B$23)^(3-1))/10000000+'3.Sizing'!$B$7*1000*('4.Cashflow'!$B$2+'2.Assumptions'!$B$36*MAX('2.Assumptions'!$B$21*$E$6-'4.Cashflow'!$B$2,0))/10000000-('3.Sizing'!$B$11*'2.Assumptions'!$B$25+'3.Sizing'!$B$12*'2.Assumptions'!$B$26)*(1+'2.Assumptions'!$B$27)^(3-1))-(MAX((MAX('3.Sizing'!$B$4*(1-'2.Assumptions'!$B$12)^(3-1)-'3.Sizing'!$B$5,0)*1000*('2.Assumptions'!$B$22*$E$6*(1+'2.Assumptions'!$B$23)^(3-1))/10000000+'3.Sizing'!$B$7*1000*('4.Cashflow'!$B$2+'2.Assumptions'!$B$36*MAX('2.Assumptions'!$B$21*$E$6-'4.Cashflow'!$B$2,0))/10000000-('3.Sizing'!$B$11*'2.Assumptions'!$B$25+'3.Sizing'!$B$12*'2.Assumptions'!$B$26)*(1+'2.Assumptions'!$B$27)^(3-1))-'3.Sizing'!$B$13/'2.Assumptions'!$B$28-IF(3<='2.Assumptions'!$B$35,('3.Sizing'!$B$13*'2.Assumptions'!$B$33-('3.Sizing'!$B$13*'2.Assumptions'!$B$33/'2.Assumptions'!$B$35)*(3-1))*'2.Assumptions'!$B$34,0),0)*'2.Assumptions'!$B$30)-(IF(3<='2.Assumptions'!$B$35,('3.Sizing'!$B$13*'2.Assumptions'!$B$33-('3.Sizing'!$B$13*'2.Assumptions'!$B$33/'2.Assumptions'!$B$35)*(3-1))*'2.Assumptions'!$B$34,0))-(IF(3<='2.Assumptions'!$B$35,('3.Sizing'!$B$13*'2.Assumptions'!$B$33)/'2.Assumptions'!$B$35,0)) -> 41.528529
A18: 4 | C18: =(MAX('3.Sizing'!$B$4*(1-'2.Assumptions'!$B$12)^(4-1)-'3.Sizing'!$B$5,0)*1000*('2.Assumptions'!$B$22*$C$6*(1+'2.Assumptions'!$B$23)^(4-1))/10000000+'3.Sizing'!$B$7*1000*('4.Cashflow'!$B$2+'2.Assumptions'!$B$36*MAX('2.Assumptions'!$B$21*$C$6-'4.Cashflow'!$B$2,0))/10000000-('3.Sizing'!$B$11*'2.Assumptions'!$B$25+'3.Sizing'!$B$12*'2.Assumptions'!$B$26)*(1+'2.Assumptions'!$B$27)^(4-1))-(MAX((MAX('3.Sizing'!$B$4*(1-'2.Assumptions'!$B$12)^(4-1)-'3.Sizing'!$B$5,0)*1000*('2.Assumptions'!$B$22*$C$6*(1+'2.Assumptions'!$B$23)^(4-1))/10000000+'3.Sizing'!$B$7*1000*('4.Cashflow'!$B$2+'2.Assumptions'!$B$36*MAX('2.Assumptions'!$B$21*$C$6-'4.Cashflow'!$B$2,0))/10000000-('3.Sizing'!$B$11*'2.Assumptions'!$B$25+'3.Sizing'!$B$12*'2.Assumptions'!$B$26)*(1+'2.Assumptions'!$B$27)^(4-1))-'3.Sizing'!$B$13/'2.Assumptions'!$B$28-IF(4<='2.Assumptions'!$B$35,('3.Sizing'!$B$13*'2.Assumptions'!$B$33-('3.Sizing'!$B$13*'2.Assumptions'!$B$33/'2.Assumptions'!$B$35)*(4-1))*'2.Assumptions'!$B$34,0),0)*'2.Assumptions'!$B$30)-(IF(4<='2.Assumptions'!$B$35,('3.Sizing'!$B$13*'2.Assumptions'!$B$33-('3.Sizing'!$B$13*'2.Assumptions'!$B$33/'2.Assumptions'!$B$35)*(4-1))*'2.Assumptions'!$B$34,0))-(IF(4<='2.Assumptions'!$B$35,('3.Sizing'!$B$13*'2.Assumptions'!$B$33)/'2.Assumptions'!$B$35,0)) -> 37.525075 | D18: =(MAX('3.Sizing'!$B$4*(1-'2.Assumptions'!$B$12)^(4-1)-'3.Sizing'!$B$5,0)*1000*('2.Assumptions'!$B$22*$D$6*(1+'2.Assumptions'!$B$23)^(4-1))/10000000+'3.Sizing'!$B$7*1000*('4.Cashflow'!$B$2+'2.Assumptions'!$B$36*MAX('2.Assumptions'!$B$21*$D$6-'4.Cashflow'!$B$2,0))/10000000-('3.Sizing'!$B$11*'2.Assumptions'!$B$25+'3.Sizing'!$B$12*'2.Assumptions'!$B$26)*(1+'2.Assumptions'!$B$27)^(4-1))-(MAX((MAX('3.Sizing'!$B$4*(1-'2.Assumptions'!$B$12)^(4-1)-'3.Sizing'!$B$5,0)*1000*('2.Assumptions'!$B$22*$D$6*(1+'2.Assumptions'!$B$23)^(4-1))/10000000+'3.Sizing'!$B$7*1000*('4.Cashflow'!$B$2+'2.Assumptions'!$B$36*MAX('2.Assumptions'!$B$21*$D$6-'4.Cashflow'!$B$2,0))/10000000-('3.Sizing'!$B$11*'2.Assumptions'!$B$25+'3.Sizing'!$B$12*'2.Assumptions'!$B$26)*(1+'2.Assumptions'!$B$27)^(4-1))-'3.Sizing'!$B$13/'2.Assumptions'!$B$28-IF(4<='2.Assumptions'!$B$35,('3.Sizing'!$B$13*'2.Assumptions'!$B$33-('3.Sizing'!$B$13*'2.Assumptions'!$B$33/'2.Assumptions'!$B$35)*(4-1))*'2.Assumptions'!$B$34,0),0)*'2.Assumptions'!$B$30)-(IF(4<='2.Assumptions'!$B$35,('3.Sizing'!$B$13*'2.Assumptions'!$B$33-('3.Sizing'!$B$13*'2.Assumptions'!$B$33/'2.Assumptions'!$B$35)*(4-1))*'2.Assumptions'!$B$34,0))-(IF(4<='2.Assumptions'!$B$35,('3.Sizing'!$B$13*'2.Assumptions'!$B$33)/'2.Assumptions'!$B$35,0)) -> 41.113688 | E18: =(MAX('3.Sizing'!$B$4*(1-'2.Assumptions'!$B$12)^(4-1)-'3.Sizing'!$B$5,0)*1000*('2.Assumptions'!$B$22*$E$6*(1+'2.Assumptions'!$B$23)^(4-1))/10000000+'3.Sizing'!$B$7*1000*('4.Cashflow'!$B$2+'2.Assumptions'!$B$36*MAX('2.Assumptions'!$B$21*$E$6-'4.Cashflow'!$B$2,0))/10000000-('3.Sizing'!$B$11*'2.Assumptions'!$B$25+'3.Sizing'!$B$12*'2.Assumptions'!$B$26)*(1+'2.Assumptions'!$B$27)^(4-1))-(MAX((MAX('3.Sizing'!$B$4*(1-'2.Assumptions'!$B$12)^(4-1)-'3.Sizing'!$B$5,0)*1000*('2.Assumptions'!$B$22*$E$6*(1+'2.Assumptions'!$B$23)^(4-1))/10000000+'3.Sizing'!$B$7*1000*('4.Cashflow'!$B$2+'2.Assumptions'!$B$36*MAX('2.Assumptions'!$B$21*$E$6-'4.Cashflow'!$B$2,0))/10000000-('3.Sizing'!$B$11*'2.Assumptions'!$B$25+'3.Sizing'!$B$12*'2.Assumptions'!$B$26)*(1+'2.Assumptions'!$B$27)^(4-1))-'3.Sizing'!$B$13/'2.Assumptions'!$B$28-IF(4<='2.Assumptions'!$B$35,('3.Sizing'!$B$13*'2.Assumptions'!$B$33-('3.Sizing'!$B$13*'2.Assumptions'!$B$33/'2.Assumptions'!$B$35)*(4-1))*'2.Assumptions'!$B$34,0),0)*'2.Assumptions'!$B$30)-(IF(4<='2.Assumptions'!$B$35,('3.Sizing'!$B$13*'2.Assumptions'!$B$33-('3.Sizing'!$B$13*'2.Assumptions'!$B$33/'2.Assumptions'!$B$35)*(4-1))*'2.Assumptions'!$B$34,0))-(IF(4<='2.Assumptions'!$B$35,('3.Sizing'!$B$13*'2.Assumptions'!$B$33)/'2.Assumptions'!$B$35,0)) -> 44.7023
A19: 5 | C19: =(MAX('3.Sizing'!$B$4*(1-'2.Assumptions'!$B$12)^(5-1)-'3.Sizing'!$B$5,0)*1000*('2.Assumptions'!$B$22*$C$6*(1+'2.Assumptions'!$B$23)^(5-1))/10000000+'3.Sizing'!$B$7*1000*('4.Cashflow'!$B$2+'2.Assumptions'!$B$36*MAX('2.Assumptions'!$B$21*$C$6-'4.Cashflow'!$B$2,0))/10000000-('3.Sizing'!$B$11*'2.Assumptions'!$B$25+'3.Sizing'!$B$12*'2.Assumptions'!$B$26)*(1+'2.Assumptions'!$B$27)^(5-1))-(MAX((MAX('3.Sizing'!$B$4*(1-'2.Assumptions'!$B$12)^(5-1)-'3.Sizing'!$B$5,0)*1000*('2.Assumptions'!$B$22*$C$6*(1+'2.Assumptions'!$B$23)^(5-1))/10000000+'3.Sizing'!$B$7*1000*('4.Cashflow'!$B$2+'2.Assumptions'!$B$36*MAX('2.Assumptions'!$B$21*$C$6-'4.Cashflow'!$B$2,0))/10000000-('3.Sizing'!$B$11*'2.Assumptions'!$B$25+'3.Sizing'!$B$12*'2.Assumptions'!$B$26)*(1+'2.Assumptions'!$B$27)^(5-1))-'3.Sizing'!$B$13/'2.Assumptions'!$B$28-IF(5<='2.Assumptions'!$B$35,('3.Sizing'!$B$13*'2.Assumptions'!$B$33-('3.Sizing'!$B$13*'2.Assumptions'!$B$33/'2.Assumptions'!$B$35)*(5-1))*'2.Assumptions'!$B$34,0),0)*'2.Assumptions'!$B$30)-(IF(5<='2.Assumptions'!$B$35,('3.Sizing'!$B$13*'2.Assumptions'!$B$33-('3.Sizing'!$B$13*'2.Assumptions'!$B$33/'2.Assumptions'!$B$35)*(5-1))*'2.Assumptions'!$B$34,0))-(IF(5<='2.Assumptions'!$B$35,('3.Sizing'!$B$13*'2.Assumptions'!$B$33)/'2.Assumptions'!$B$35,0)) -> 40.536428 | D19: =(MAX('3.Sizing'!$B$4*(1-'2.Assumptions'!$B$12)^(5-1)-'3.Sizing'!$B$5,0)*1000*('2.Assumptions'!$B$22*$D$6*(1+'2.Assumptions'!$B$23)^(5-1))/10000000+'3.Sizing'!$B$7*1000*('4.Cashflow'!$B$2+'2.Assumptions'!$B$36*MAX('2.Assumptions'!$B$21*$D$6-'4.Cashflow'!$B$2,0))/10000000-('3.Sizing'!$B$11*'2.Assumptions'!$B$25+'3.Sizing'!$B$12*'2.Assumptions'!$B$26)*(1+'2.Assumptions'!$B$27)^(5-1))-(MAX((MAX('3.Sizing'!$B$4*(1-'2.Assumptions'!$B$12)^(5-1)-'3.Sizing'!$B$5,0)*1000*('2.Assumptions'!$B$22*$D$6*(1+'2.Assumptions'!$B$23)^(5-1))/10000000+'3.Sizing'!$B$7*1000*('4.Cashflow'!$B$2+'2.Assumptions'!$B$36*MAX('2.Assumptions'!$B$21*$D$6-'4.Cashflow'!$B$2,0))/10000000-('3.Sizing'!$B$11*'2.Assumptions'!$B$25+'3.Sizing'!$B$12*'2.Assumptions'!$B$26)*(1+'2.Assumptions'!$B$27)^(5-1))-'3.Sizing'!$B$13/'2.Assumptions'!$B$28-IF(5<='2.Assumptions'!$B$35,('3.Sizing'!$B$13*'2.Assumptions'!$B$33-('3.Sizing'!$B$13*'2.Assumptions'!$B$33/'2.Assumptions'!$B$35)*(5-1))*'2.Assumptions'!$B$34,0),0)*'2.Assumptions'!$B$30)-(IF(5<='2.Assumptions'!$B$35,('3.Sizing'!$B$13*'2.Assumptions'!$B$33-('3.Sizing'!$B$13*'2.Assumptions'!$B$33/'2.Assumptions'!$B$35)*(5-1))*'2.Assumptions'!$B$34,0))-(IF(5<='2.Assumptions'!$B$35,('3.Sizing'!$B$13*'2.Assumptions'!$B$33)/'2.Assumptions'!$B$35,0)) -> 44.19828 | E19: =(MAX('3.Sizing'!$B$4*(1-'2.Assumptions'!$B$12)^(5-1)-'3.Sizing'!$B$5,0)*1000*('2.Assumptions'!$B$22*$E$6*(1+'2.Assumptions'!$B$23)^(5-1))/10000000+'3.Sizing'!$B$7*1000*('4.Cashflow'!$B$2+'2.Assumptions'!$B$36*MAX('2.Assumptions'!$B$21*$E$6-'4.Cashflow'!$B$2,0))/10000000-('3.Sizing'!$B$11*'2.Assumptions'!$B$25+'3.Sizing'!$B$12*'2.Assumptions'!$B$26)*(1+'2.Assumptions'!$B$27)^(5-1))-(MAX((MAX('3.Sizing'!$B$4*(1-'2.Assumptions'!$B$12)^(5-1)-'3.Sizing'!$B$5,0)*1000*('2.Assumptions'!$B$22*$E$6*(1+'2.Assumptions'!$B$23)^(5-1))/10000000+'3.Sizing'!$B$7*1000*('4.Cashflow'!$B$2+'2.Assumptions'!$B$36*MAX('2.Assumptions'!$B$21*$E$6-'4.Cashflow'!$B$2,0))/10000000-('3.Sizing'!$B$11*'2.Assumptions'!$B$25+'3.Sizing'!$B$12*'2.Assumptions'!$B$26)*(1+'2.Assumptions'!$B$27)^(5-1))-'3.Sizing'!$B$13/'2.Assumptions'!$B$28-IF(5<='2.Assumptions'!$B$35,('3.Sizing'!$B$13*'2.Assumptions'!$B$33-('3.Sizing'!$B$13*'2.Assumptions'!$B$33/'2.Assumptions'!$B$35)*(5-1))*'2.Assumptions'!$B$34,0),0)*'2.Assumptions'!$B$30)-(IF(5<='2.Assumptions'!$B$35,('3.Sizing'!$B$13*'2.Assumptions'!$B$33-('3.Sizing'!$B$13*'2.Assumptions'!$B$33/'2.Assumptions'!$B$35)*(5-1))*'2.Assumptions'!$B$34,0))-(IF(5<='2.Assumptions'!$B$35,('3.Sizing'!$B$13*'2.Assumptions'!$B$33)/'2.Assumptions'!$B$35,0)) -> 47.860133
A20: 6 | C20: =(MAX('3.Sizing'!$B$4*(1-'2.Assumptions'!$B$12)^(6-1)-'3.Sizing'!$B$5,0)*1000*('2.Assumptions'!$B$22*$C$6*(1+'2.Assumptions'!$B$23)^(6-1))/10000000+'3.Sizing'!$B$7*1000*('4.Cashflow'!$B$2+'2.Assumptions'!$B$36*MAX('2.Assumptions'!$B$21*$C$6-'4.Cashflow'!$B$2,0))/10000000-('3.Sizing'!$B$11*'2.Assumptions'!$B$25+'3.Sizing'!$B$12*'2.Assumptions'!$B$26)*(1+'2.Assumptions'!$B$27)^(6-1))-(MAX((MAX('3.Sizing'!$B$4*(1-'2.Assumptions'!$B$12)^(6-1)-'3.Sizing'!$B$5,0)*1000*('2.Assumptions'!$B$22*$C$6*(1+'2.Assumptions'!$B$23)^(6-1))/10000000+'3.Sizing'!$B$7*1000*('4.Cashflow'!$B$2+'2.Assumptions'!$B$36*MAX('2.Assumptions'!$B$21*$C$6-'4.Cashflow'!$B$2,0))/10000000-('3.Sizing'!$B$11*'2.Assumptions'!$B$25+'3.Sizing'!$B$12*'2.Assumptions'!$B$26)*(1+'2.Assumptions'!$B$27)^(6-1))-'3.Sizing'!$B$13/'2.Assumptions'!$B$28-IF(6<='2.Assumptions'!$B$35,('3.Sizing'!$B$13*'2.Assumptions'!$B$33-('3.Sizing'!$B$13*'2.Assumptions'!$B$33/'2.Assumptions'!$B$35)*(6-1))*'2.Assumptions'!$B$34,0),0)*'2.Assumptions'!$B$30)-(IF(6<='2.Assumptions'!$B$35,('3.Sizing'!$B$13*'2.Assumptions'!$B$33-('3.Sizing'!$B$13*'2.Assumptions'!$B$33/'2.Assumptions'!$B$35)*(6-1))*'2.Assumptions'!$B$34,0))-(IF(6<='2.Assumptions'!$B$35,('3.Sizing'!$B$13*'2.Assumptions'!$B$33)/'2.Assumptions'!$B$35,0)) -> 43.527842 | D20: =(MAX('3.Sizing'!$B$4*(1-'2.Assumptions'!$B$12)^(6-1)-'3.Sizing'!$B$5,0)*1000*('2.Assumptions'!$B$22*$D$6*(1+'2.Assumptions'!$B$23)^(6-1))/10000000+'3.Sizing'!$B$7*1000*('4.Cashflow'!$B$2+'2.Assumptions'!$B$36*MAX('2.Assumptions'!$B$21*$D$6-'4.Cashflow'!$B$2,0))/10000000-('3.Sizing'!$B$11*'2.Assumptions'!$B$25+'3.Sizing'!$B$12*'2.Assumptions'!$B$26)*(1+'2.Assumptions'!$B$27)^(6-1))-(MAX((MAX('3.Sizing'!$B$4*(1-'2.Assumptions'!$B$12)^(6-1)-'3.Sizing'!$B$5,0)*1000*('2.Assumptions'!$B$22*$D$6*(1+'2.Assumptions'!$B$23)^(6-1))/10000000+'3.Sizing'!$B$7*1000*('4.Cashflow'!$B$2+'2.Assumptions'!$B$36*MAX('2.Assumptions'!$B$21*$D$6-'4.Cashflow'!$B$2,0))/10000000-('3.Sizing'!$B$11*'2.Assumptions'!$B$25+'3.Sizing'!$B$12*'2.Assumptions'!$B$26)*(1+'2.Assumptions'!$B$27)^(6-1))-'3.Sizing'!$B$13/'2.Assumptions'!$B$28-IF(6<='2.Assumptions'!$B$35,('3.Sizing'!$B$13*'2.Assumptions'!$B$33-('3.Sizing'!$B$13*'2.Assumptions'!$B$33/'2.Assumptions'!$B$35)*(6-1))*'2.Assumptions'!$B$34,0),0)*'2.Assumptions'!$B$30)-(IF(6<='2.Assumptions'!$B$35,('3.Sizing'!$B$13*'2.Assumptions'!$B$33-('3.Sizing'!$B$13*'2.Assumptions'!$B$33/'2.Assumptions'!$B$35)*(6-1))*'2.Assumptions'!$B$34,0))-(IF(6<='2.Assumptions'!$B$35,('3.Sizing'!$B$13*'2.Assumptions'!$B$33)/'2.Assumptions'!$B$35,0)) -> 47.264276 | E20: =(MAX('3.Sizing'!$B$4*(1-'2.Assumptions'!$B$12)^(6-1)-'3.Sizing'!$B$5,0)*1000*('2.Assumptions'!$B$22*$E$6*(1+'2.Assumptions'!$B$23)^(6-1))/10000000+'3.Sizing'!$B$7*1000*('4.Cashflow'!$B$2+'2.Assumptions'!$B$36*MAX('2.Assumptions'!$B$21*$E$6-'4.Cashflow'!$B$2,0))/10000000-('3.Sizing'!$B$11*'2.Assumptions'!$B$25+'3.Sizing'!$B$12*'2.Assumptions'!$B$26)*(1+'2.Assumptions'!$B$27)^(6-1))-(MAX((MAX('3.Sizing'!$B$4*(1-'2.Assumptions'!$B$12)^(6-1)-'3.Sizing'!$B$5,0)*1000*('2.Assumptions'!$B$22*$E$6*(1+'2.Assumptions'!$B$23)^(6-1))/10000000+'3.Sizing'!$B$7*1000*('4.Cashflow'!$B$2+'2.Assumptions'!$B$36*MAX('2.Assumptions'!$B$21*$E$6-'4.Cashflow'!$B$2,0))/10000000-('3.Sizing'!$B$11*'2.Assumptions'!$B$25+'3.Sizing'!$B$12*'2.Assumptions'!$B$26)*(1+'2.Assumptions'!$B$27)^(6-1))-'3.Sizing'!$B$13/'2.Assumptions'!$B$28-IF(6<='2.Assumptions'!$B$35,('3.Sizing'!$B$13*'2.Assumptions'!$B$33-('3.Sizing'!$B$13*'2.Assumptions'!$B$33/'2.Assumptions'!$B$35)*(6-1))*'2.Assumptions'!$B$34,0),0)*'2.Assumptions'!$B$30)-(IF(6<='2.Assumptions'!$B$35,('3.Sizing'!$B$13*'2.Assumptions'!$B$33-('3.Sizing'!$B$13*'2.Assumptions'!$B$33/'2.Assumptions'!$B$35)*(6-1))*'2.Assumptions'!$B$34,0))-(IF(6<='2.Assumptions'!$B$35,('3.Sizing'!$B$13*'2.Assumptions'!$B$33)/'2.Assumptions'!$B$35,0)) -> 51.000711
A21: 7 | C21: =(MAX('3.Sizing'!$B$4*(1-'2.Assumptions'!$B$12)^(7-1)-'3.Sizing'!$B$5,0)*1000*('2.Assumptions'!$B$22*$C$6*(1+'2.Assumptions'!$B$23)^(7-1))/10000000+'3.Sizing'!$B$7*1000*('4.Cashflow'!$B$2+'2.Assumptions'!$B$36*MAX('2.Assumptions'!$B$21*$C$6-'4.Cashflow'!$B$2,0))/10000000-('3.Sizing'!$B$11*'2.Assumptions'!$B$25+'3.Sizing'!$B$12*'2.Assumptions'!$B$26)*(1+'2.Assumptions'!$B$27)^(7-1))-(MAX((MAX('3.Sizing'!$B$4*(1-'2.Assumptions'!$B$12)^(7-1)-'3.Sizing'!$B$5,0)*1000*('2.Assumptions'!$B$22*$C$6*(1+'2.Assumptions'!$B$23)^(7-1))/10000000+'3.Sizing'!$B$7*1000*('4.Cashflow'!$B$2+'2.Assumptions'!$B$36*MAX('2.Assumptions'!$B$21*$C$6-'4.Cashflow'!$B$2,0))/10000000-('3.Sizing'!$B$11*'2.Assumptions'!$B$25+'3.Sizing'!$B$12*'2.Assumptions'!$B$26)*(1+'2.Assumptions'!$B$27)^(7-1))-'3.Sizing'!$B$13/'2.Assumptions'!$B$28-IF(7<='2.Assumptions'!$B$35,('3.Sizing'!$B$13*'2.Assumptions'!$B$33-('3.Sizing'!$B$13*'2.Assumptions'!$B$33/'2.Assumptions'!$B$35)*(7-1))*'2.Assumptions'!$B$34,0),0)*'2.Assumptions'!$B$30)-(IF(7<='2.Assumptions'!$B$35,('3.Sizing'!$B$13*'2.Assumptions'!$B$33-('3.Sizing'!$B$13*'2.Assumptions'!$B$33/'2.Assumptions'!$B$35)*(7-1))*'2.Assumptions'!$B$34,0))-(IF(7<='2.Assumptions'!$B$35,('3.Sizing'!$B$13*'2.Assumptions'!$B$33)/'2.Assumptions'!$B$35,0)) -> 46.497888 | D21: =(MAX('3.Sizing'!$B$4*(1-'2.Assumptions'!$B$12)^(7-1)-'3.Sizing'!$B$5,0)*1000*('2.Assumptions'!$B$22*$D$6*(1+'2.Assumptions'!$B$23)^(7-1))/10000000+'3.Sizing'!$B$7*1000*('4.Cashflow'!$B$2+'2.Assumptions'!$B$36*MAX('2.Assumptions'!$B$21*$D$6-'4.Cashflow'!$B$2,0))/10000000-('3.Sizing'!$B$11*'2.Assumptions'!$B$25+'3.Sizing'!$B$12*'2.Assumptions'!$B$26)*(1+'2.Assumptions'!$B$27)^(7-1))-(MAX((MAX('3.Sizing'!$B$4*(1-'2.Assumptions'!$B$12)^(7-1)-'3.Sizing'!$B$5,0)*1000*('2.Assumptions'!$B$22*$D$6*(1+'2.Assumptions'!$B$23)^(7-1))/10000000+'3.Sizing'!$B$7*1000*('4.Cashflow'!$B$2+'2.Assumptions'!$B$36*MAX('2.Assumptions'!$B$21*$D$6-'4.Cashflow'!$B$2,0))/10000000-('3.Sizing'!$B$11*'2.Assumptions'!$B$25+'3.Sizing'!$B$12*'2.Assumptions'!$B$26)*(1+'2.Assumptions'!$B$27)^(7-1))-'3.Sizing'!$B$13/'2.Assumptions'!$B$28-IF(7<='2.Assumptions'!$B$35,('3.Sizing'!$B$13*'2.Assumptions'!$B$33-('3.Sizing'!$B$13*'2.Assumptions'!$B$33/'2.Assumptions'!$B$35)*(7-1))*'2.Assumptions'!$B$34,0),0)*'2.Assumptions'!$B$30)-(IF(7<='2.Assumptions'!$B$35,('3.Sizing'!$B$13*'2.Assumptions'!$B$33-('3.Sizing'!$B$13*'2.Assumptions'!$B$33/'2.Assumptions'!$B$35)*(7-1))*'2.Assumptions'!$B$34,0))-(IF(7<='2.Assumptions'!$B$35,('3.Sizing'!$B$13*'2.Assumptions'!$B$33)/'2.Assumptions'!$B$35,0)) -> 50.310266 | E21: =(MAX('3.Sizing'!$B$4*(1-'2.Assumptions'!$B$12)^(7-1)-'3.Sizing'!$B$5,0)*1000*('2.Assumptions'!$B$22*$E$6*(1+'2.Assumptions'!$B$23)^(7-1))/10000000+'3.Sizing'!$B$7*1000*('4.Cashflow'!$B$2+'2.Assumptions'!$B$36*MAX('2.Assumptions'!$B$21*$E$6-'4.Cashflow'!$B$2,0))/10000000-('3.Sizing'!$B$11*'2.Assumptions'!$B$25+'3.Sizing'!$B$12*'2.Assumptions'!$B$26)*(1+'2.Assumptions'!$B$27)^(7-1))-(MAX((MAX('3.Sizing'!$B$4*(1-'2.Assumptions'!$B$12)^(7-1)-'3.Sizing'!$B$5,0)*1000*('2.Assumptions'!$B$22*$E$6*(1+'2.Assumptions'!$B$23)^(7-1))/10000000+'3.Sizing'!$B$7*1000*('4.Cashflow'!$B$2+'2.Assumptions'!$B$36*MAX('2.Assumptions'!$B$21*$E$6-'4.Cashflow'!$B$2,0))/10000000-('3.Sizing'!$B$11*'2.Assumptions'!$B$25+'3.Sizing'!$B$12*'2.Assumptions'!$B$26)*(1+'2.Assumptions'!$B$27)^(7-1))-'3.Sizing'!$B$13/'2.Assumptions'!$B$28-IF(7<='2.Assumptions'!$B$35,('3.Sizing'!$B$13*'2.Assumptions'!$B$33-('3.Sizing'!$B$13*'2.Assumptions'!$B$33/'2.Assumptions'!$B$35)*(7-1))*'2.Assumptions'!$B$34,0),0)*'2.Assumptions'!$B$30)-(IF(7<='2.Assumptions'!$B$35,('3.Sizing'!$B$13*'2.Assumptions'!$B$33-('3.Sizing'!$B$13*'2.Assumptions'!$B$33/'2.Assumptions'!$B$35)*(7-1))*'2.Assumptions'!$B$34,0))-(IF(7<='2.Assumptions'!$B$35,('3.Sizing'!$B$13*'2.Assumptions'!$B$33)/'2.Assumptions'!$B$35,0)) -> 54.122644
A22: 8 | C22: =(MAX('3.Sizing'!$B$4*(1-'2.Assumptions'!$B$12)^(8-1)-'3.Sizing'!$B$5,0)*1000*('2.Assumptions'!$B$22*$C$6*(1+'2.Assumptions'!$B$23)^(8-1))/10000000+'3.Sizing'!$B$7*1000*('4.Cashflow'!$B$2+'2.Assumptions'!$B$36*MAX('2.Assumptions'!$B$21*$C$6-'4.Cashflow'!$B$2,0))/10000000-('3.Sizing'!$B$11*'2.Assumptions'!$B$25+'3.Sizing'!$B$12*'2.Assumptions'!$B$26)*(1+'2.Assumptions'!$B$27)^(8-1))-(MAX((MAX('3.Sizing'!$B$4*(1-'2.Assumptions'!$B$12)^(8-1)-'3.Sizing'!$B$5,0)*1000*('2.Assumptions'!$B$22*$C$6*(1+'2.Assumptions'!$B$23)^(8-1))/10000000+'3.Sizing'!$B$7*1000*('4.Cashflow'!$B$2+'2.Assumptions'!$B$36*MAX('2.Assumptions'!$B$21*$C$6-'4.Cashflow'!$B$2,0))/10000000-('3.Sizing'!$B$11*'2.Assumptions'!$B$25+'3.Sizing'!$B$12*'2.Assumptions'!$B$26)*(1+'2.Assumptions'!$B$27)^(8-1))-'3.Sizing'!$B$13/'2.Assumptions'!$B$28-IF(8<='2.Assumptions'!$B$35,('3.Sizing'!$B$13*'2.Assumptions'!$B$33-('3.Sizing'!$B$13*'2.Assumptions'!$B$33/'2.Assumptions'!$B$35)*(8-1))*'2.Assumptions'!$B$34,0),0)*'2.Assumptions'!$B$30)-(IF(8<='2.Assumptions'!$B$35,('3.Sizing'!$B$13*'2.Assumptions'!$B$33-('3.Sizing'!$B$13*'2.Assumptions'!$B$33/'2.Assumptions'!$B$35)*(8-1))*'2.Assumptions'!$B$34,0))-(IF(8<='2.Assumptions'!$B$35,('3.Sizing'!$B$13*'2.Assumptions'!$B$33)/'2.Assumptions'!$B$35,0)) -> 49.445056 | D22: =(MAX('3.Sizing'!$B$4*(1-'2.Assumptions'!$B$12)^(8-1)-'3.Sizing'!$B$5,0)*1000*('2.Assumptions'!$B$22*$D$6*(1+'2.Assumptions'!$B$23)^(8-1))/10000000+'3.Sizing'!$B$7*1000*('4.Cashflow'!$B$2+'2.Assumptions'!$B$36*MAX('2.Assumptions'!$B$21*$D$6-'4.Cashflow'!$B$2,0))/10000000-('3.Sizing'!$B$11*'2.Assumptions'!$B$25+'3.Sizing'!$B$12*'2.Assumptions'!$B$26)*(1+'2.Assumptions'!$B$27)^(8-1))-(MAX((MAX('3.Sizing'!$B$4*(1-'2.Assumptions'!$B$12)^(8-1)-'3.Sizing'!$B$5,0)*1000*('2.Assumptions'!$B$22*$D$6*(1+'2.Assumptions'!$B$23)^(8-1))/10000000+'3.Sizing'!$B$7*1000*('4.Cashflow'!$B$2+'2.Assumptions'!$B$36*MAX('2.Assumptions'!$B$21*$D$6-'4.Cashflow'!$B$2,0))/10000000-('3.Sizing'!$B$11*'2.Assumptions'!$B$25+'3.Sizing'!$B$12*'2.Assumptions'!$B$26)*(1+'2.Assumptions'!$B$27)^(8-1))-'3.Sizing'!$B$13/'2.Assumptions'!$B$28-IF(8<='2.Assumptions'!$B$35,('3.Sizing'!$B$13*'2.Assumptions'!$B$33-('3.Sizing'!$B$13*'2.Assumptions'!$B$33/'2.Assumptions'!$B$35)*(8-1))*'2.Assumptions'!$B$34,0),0)*'2.Assumptions'!$B$30)-(IF(8<='2.Assumptions'!$B$35,('3.Sizing'!$B$13*'2.Assumptions'!$B$33-('3.Sizing'!$B$13*'2.Assumptions'!$B$33/'2.Assumptions'!$B$35)*(8-1))*'2.Assumptions'!$B$34,0))-(IF(8<='2.Assumptions'!$B$35,('3.Sizing'!$B$13*'2.Assumptions'!$B$33)/'2.Assumptions'!$B$35,0)) -> 53.334758 | E22: =(MAX('3.Sizing'!$B$4*(1-'2.Assumptions'!$B$12)^(8-1)-'3.Sizing'!$B$5,0)*1000*('2.Assumptions'!$B$22*$E$6*(1+'2.Assumptions'!$B$23)^(8-1))/10000000+'3.Sizing'!$B$7*1000*('4.Cashflow'!$B$2+'2.Assumptions'!$B$36*MAX('2.Assumptions'!$B$21*$E$6-'4.Cashflow'!$B$2,0))/10000000-('3.Sizing'!$B$11*'2.Assumptions'!$B$25+'3.Sizing'!$B$12*'2.Assumptions'!$B$26)*(1+'2.Assumptions'!$B$27)^(8-1))-(MAX((MAX('3.Sizing'!$B$4*(1-'2.Assumptions'!$B$12)^(8-1)-'3.Sizing'!$B$5,0)*1000*('2.Assumptions'!$B$22*$E$6*(1+'2.Assumptions'!$B$23)^(8-1))/10000000+'3.Sizing'!$B$7*1000*('4.Cashflow'!$B$2+'2.Assumptions'!$B$36*MAX('2.Assumptions'!$B$21*$E$6-'4.Cashflow'!$B$2,0))/10000000-('3.Sizing'!$B$11*'2.Assumptions'!$B$25+'3.Sizing'!$B$12*'2.Assumptions'!$B$26)*(1+'2.Assumptions'!$B$27)^(8-1))-'3.Sizing'!$B$13/'2.Assumptions'!$B$28-IF(8<='2.Assumptions'!$B$35,('3.Sizing'!$B$13*'2.Assumptions'!$B$33-('3.Sizing'!$B$13*'2.Assumptions'!$B$33/'2.Assumptions'!$B$35)*(8-1))*'2.Assumptions'!$B$34,0),0)*'2.Assumptions'!$B$30)-(IF(8<='2.Assumptions'!$B$35,('3.Sizing'!$B$13*'2.Assumptions'!$B$33-('3.Sizing'!$B$13*'2.Assumptions'!$B$33/'2.Assumptions'!$B$35)*(8-1))*'2.Assumptions'!$B$34,0))-(IF(8<='2.Assumptions'!$B$35,('3.Sizing'!$B$13*'2.Assumptions'!$B$33)/'2.Assumptions'!$B$35,0)) -> 57.224459
